{
  "meta": [
    {
      "key": "parapet",
      "char": "H"
    },
    {
      "key": "capstone",
      "char": "'"
    },
    {
      "key": "girder",
      "char": "M"
    },
    {
      "key": "beam",
      "char": "0"
    },
    {
      "key": "pier",
      "char": "s"
    },
    {
      "key": "piercap",
      "char": "j"
    },
    {
      "key": "footing",
      "char": "j"
    },
    {
      "key": "brace",
      "char": "P"
    },
    {
      "key": "cablex",
      "char": "6"
    },
    {
      "key": "cablez",
      "char": "7"
    },
    {
      "key": "hanger",
      "char": "5"
    },
    {
      "key": "lamp",
      "char": "2"
    },
    {
      "key": "debris",
      "char": "m"
    }
  ],
  "xsize": 16,
  "zsize": 16,
  "slices": [
    [
      "                ",
      "                ",
      "                ",
      "                ",
      "                ",
      "                ",
      "                ",
      "                ",
      "                ",
      "                ",
      "                ",
      "                ",
      "                ",
      "                ",
      "                ",
      "                "
    ],
    [
      "       MM       ",
      "       MM       ",
      "                ",
      "qsssqsssqsssqsss",
      "                ",
      "                ",
      "                ",
      "                ",
      "                ",
      "                ",
      "                ",
      "                ",
      "qsssqsssqsssqsss",
      "                ",
      "       MM       ",
      "       MM       "
    ],
    [
      "       MM       ",
      "       MM       ",
      "                ",
      "qsssqsssqsssqsss",
      "                ",
      "                ",
      "                ",
      "                ",
      "                ",
      "                ",
      "                ",
      "                ",
      "qsssqsssqsssqsss",
      "                ",
      "       MM       ",
      "       MM       "
    ],
    [
      "       MM       ",
      "       MM       ",
      "                ",
      "qrrrqrrrqrrrqrrr",
      "                ",
      "                ",
      "                ",
      "                ",
      "                ",
      "                ",
      "                ",
      "                ",
      "qrrrqrrrqrrrqrrr",
      "                ",
      "       MM       ",
      "       MM       "
    ],
    [
      "       NN       ",
      "       NN       ",
      "                ",
      "qsrsqsrsqsrsqsrs",
      "                ",
      "                ",
      "                ",
      "                ",
      "                ",
      "                ",
      "                ",
      "                ",
      "qsrsqsrsqsrsqsrs",
      "                ",
      "       NN       ",
      "       NN       "
    ],
    [
      "       MM       ",
      "       MM       ",
      "k   k  88   k   ",
      "qsssqsssqsssqsss",
      "                ",
      "  8     8     8 ",
      "                ",
      "                ",
      "                ",
      "                ",
      "  8     8     8 ",
      "                ",
      "qsssqsssqsssqsss",
      "k   k  88   k   ",
      "       MM       ",
      "       MM       "
    ],
    [
      "       MM       ",
      "       MM       ",
      "qqqqqqqMMqqqqqqq",
      "qqqqqqqMMqqqqqqq",
      "qqqqqqqMMqqqqqqq",
      "qqqqqqqMMqqqqqqq",
      "qqqqqqqMMqqqqqqq",
      "qqqqqqqMMqqqqqqq",
      "qqqqqqqMMqqqqqqq",
      "qqqqqqqMMqqqqqqq",
      "qqqqqqqMMqqqqqqq",
      "qqqqqqqMMqqqqqqq",
      "qqqqqqqMMqqqqqqq",
      "qqqqqqqMMqqqqqqq",
      "       MM       ",
      "       MM       "
    ],
    [
      "       MM       ",
      "       MM       ",
      "                ",
      "                ",
      "                ",
      "                ",
      "                ",
      "0000000000000000",
      "0000000000000000",
      "                ",
      "                ",
      "                ",
      "                ",
      "                ",
      "       MM       ",
      "       MM       "
    ],
    [
      "       MM       ",
      "       MM       ",
      "       PP       ",
      "       PP       ",
      "       PP       ",
      "       PP       ",
      "       PP       ",
      "       PP       ",
      "       PP       ",
      "       PP       ",
      "       PP       ",
      "       PP       ",
      "       PP       ",
      "       PP       ",
      "       MM       ",
      "       MM       "
    ],
    [
      "       NN       ",
      "       NN       ",
      "       PP       ",
      "       PP       ",
      "       PP       ",
      "       PP       ",
      "       PP       ",
      "       PP       ",
      "       PP       ",
      "       PP       ",
      "       PP       ",
      "       PP       ",
      "       PP       ",
      "       PP       ",
      "       NN       ",
      "       NN       "
    ],
    [
      "       MM       ",
      "       MM       ",
      "                ",
      "                ",
      "                ",
      "                ",
      "                ",
      "                ",
      "                ",
      "                ",
      "                ",
      "                ",
      "                ",
      "                ",
      "       MM       ",
      "       MM       "
    ],
    [
      "       MM       ",
      "       MM       ",
      "       MM       ",
      "       MM       ",
      "       MM       ",
      "       MM       ",
      "       MM       ",
      "       MM       ",
      "       MM       ",
      "       MM       ",
      "       MM       ",
      "       MM       ",
      "       MM       ",
      "       MM       ",
      "       MM       ",
      "       MM       "
    ],
    [
      "       MM       ",
      "       MM       ",
      "       PP       ",
      "       PP       ",
      "       PP       ",
      "       PP       ",
      "       PP       ",
      "       PP       ",
      "       PP       ",
      "       PP       ",
      "       PP       ",
      "       PP       ",
      "       PP       ",
      "       PP       ",
      "       MM       ",
      "       MM       "
    ],
    [
      "       MM       ",
      "       MM       ",
      "       PP       ",
      "       PP       ",
      "       PP       ",
      "       PP       ",
      "       PP       ",
      "       PP       ",
      "       PP       ",
      "       PP       ",
      "       PP       ",
      "       PP       ",
      "       PP       ",
      "       PP       ",
      "       MM       ",
      "       MM       "
    ],
    [
      "       NN       ",
      "       NN       ",
      "                ",
      "                ",
      "                ",
      "                ",
      "                ",
      "                ",
      "                ",
      "                ",
      "                ",
      "                ",
      "                ",
      "                ",
      "       NN       ",
      "       NN       "
    ],
    [
      "       MM       ",
      "       MM       ",
      "       MM       ",
      "       MM       ",
      "       MM       ",
      "       MM       ",
      "       MM       ",
      "       MM       ",
      "       MM       ",
      "       MM       ",
      "       MM       ",
      "       MM       ",
      "       MM       ",
      "       MM       ",
      "       MM       ",
      "       MM       "
    ],
    [
      "       MM       ",
      "       MM       ",
      "       MM       ",
      "       MM       ",
      "       MM       ",
      "       MM       ",
      "       MM       ",
      "       VM       ",
      "       MV       ",
      "       MM       ",
      "       MM       ",
      "       MM       ",
      "       MM       ",
      "       MM       ",
      "       MM       ",
      "       MM       "
    ]
  ],
  "palette": {
    "palette": [
      {
        "char": "M",
        "blocks": [
          {
            "random": 34,
            "block": "minecraft:deepslate_tiles"
          },
          {
            "random": 26,
            "block": "minecraft:cracked_deepslate_tiles"
          },
          {
            "random": 22,
            "block": "minecraft:polished_deepslate"
          },
          {
            "random": 1000,
            "block": "minecraft:deepslate_bricks"
          }
        ],
        "damaged": "minecraft:iron_bars"
      },
      {
        "char": "N",
        "blocks": [
          {
            "random": 36,
            "block": "minecraft:weathered_copper"
          },
          {
            "random": 28,
            "block": "minecraft:exposed_copper"
          },
          {
            "random": 24,
            "block": "minecraft:oxidized_copper"
          },
          {
            "random": 1000,
            "block": "minecraft:copper_block"
          }
        ]
      },
      {
        "char": "j",
        "block": "minecraft:polished_deepslate"
      },
      {
        "char": "P",
        "blocks": [
          {
            "random": 40,
            "block": "minecraft:oxidized_copper_bars"
          },
          {
            "random": 34,
            "block": "minecraft:weathered_copper_bars"
          },
          {
            "random": 26,
            "block": "minecraft:exposed_copper_bars"
          },
          {
            "random": 1000,
            "block": "minecraft:copper_bars"
          }
        ]
      },
      {
        "char": "<",
        "block": "minecraft:deepslate_tile_stairs[facing=west,half=bottom,shape=straight]"
      },
      {
        "char": ">",
        "block": "minecraft:deepslate_tile_stairs[facing=east,half=bottom,shape=straight]"
      },
      {
        "char": "k",
        "block": "minecraft:deepslate_tile_slab[type=bottom]"
      },
      {
        "char": "0",
        "block": "minecraft:deepslate_tile_slab[type=top]"
      },
      {
        "char": "H",
        "blocks": [
          {
            "random": 44,
            "block": "minecraft:stone_brick_wall"
          },
          {
            "random": 30,
            "block": "minecraft:mossy_stone_brick_wall"
          },
          {
            "random": 1000,
            "block": "minecraft:cobblestone_wall"
          }
        ]
      },
      {
        "char": "'",
        "blocks": [
          {
            "random": 88,
            "block": "minecraft:stone_brick_slab[type=bottom]"
          },
          {
            "random": 1000,
            "block": "minecraft:mossy_stone_brick_slab[type=bottom]"
          }
        ]
      },
      {
        "char": "s",
        "blocks": [
          {
            "random": 34,
            "block": "minecraft:mossy_stone_bricks"
          },
          {
            "random": 26,
            "block": "minecraft:mossy_cobblestone"
          },
          {
            "random": 24,
            "block": "minecraft:cracked_stone_bricks"
          },
          {
            "random": 1000,
            "block": "minecraft:stone_bricks"
          }
        ]
      },
      {
        "char": "q",
        "blocks": [
          {
            "random": 40,
            "block": "minecraft:deepslate_tiles"
          },
          {
            "random": 30,
            "block": "minecraft:cracked_deepslate_tiles"
          },
          {
            "random": 1000,
            "block": "minecraft:tuff_bricks"
          }
        ]
      },
      {
        "char": "r",
        "blocks": [
          {
            "random": 46,
            "block": "minecraft:gray_stained_glass_pane"
          },
          {
            "random": 22,
            "block": "minecraft:glass_pane"
          },
          {
            "random": 1000,
            "block": "minecraft:air"
          }
        ]
      },
      {
        "char": "5",
        "block": "minecraft:iron_chain[axis=y,waterlogged=false]"
      },
      {
        "char": "6",
        "block": "minecraft:iron_chain[axis=x,waterlogged=false]"
      },
      {
        "char": "7",
        "block": "minecraft:iron_chain[axis=z,waterlogged=false]"
      },
      {
        "char": "2",
        "block": "minecraft:lantern[hanging=false,waterlogged=false]",
        "torch": true
      },
      {
        "char": "8",
        "block": "minecraft:lantern[hanging=true,waterlogged=false]",
        "torch": true
      },
      {
        "char": "3",
        "blocks": [
          {
            "random": 52,
            "block": "minecraft:lantern[hanging=true,waterlogged=false]"
          },
          {
            "random": 1000,
            "block": "minecraft:air"
          }
        ],
        "torch": true
      },
      {
        "char": "e",
        "blocks": [
          {
            "random": 44,
            "block": "minecraft:green_concrete"
          },
          {
            "random": 30,
            "block": "minecraft:white_concrete"
          },
          {
            "random": 1000,
            "block": "minecraft:gray_concrete"
          }
        ]
      },
      {
        "char": "m",
        "blocks": [
          {
            "random": 46,
            "block": "minecraft:cobweb"
          },
          {
            "random": 1000,
            "block": "minecraft:air"
          }
        ]
      },
      {
        "char": "I",
        "blocks": [
          {
            "random": 78,
            "block": "minecraft:iron_bars"
          },
          {
            "random": 1000,
            "block": "minecraft:air"
          }
        ]
      },
      {
        "char": "J",
        "blocks": [
          {
            "random": 26,
            "block": "minecraft:cracked_deepslate_tiles"
          },
          {
            "random": 22,
            "block": "minecraft:cobweb"
          },
          {
            "random": 20,
            "block": "minecraft:deepslate_tile_slab[type=bottom]"
          },
          {
            "random": 1000,
            "block": "minecraft:air"
          }
        ]
      },
      {
        "char": "&",
        "blocks": [
          {
            "random": 62,
            "block": "minecraft:red_concrete"
          },
          {
            "random": 1000,
            "block": "minecraft:white_concrete"
          }
        ]
      },
      {
        "char": "V",
        "block": "minecraft:redstone_lamp[lit=true]",
        "torch": true
      },
      {
        "char": "n",
        "block": "minecraft:vine[north=true,east=false,south=false,west=false,up=false]"
      },
      {
        "char": ",",
        "block": "minecraft:vine[north=false,east=false,south=true,west=false,up=false]"
      }
    ]
  }
}
