{
  "xsize": 16,
  "zsize": 16,
  "slices": [
    [
      "################",
      "################",
      "################",
      "################",
      "################",
      "#####d##########",
      "################",
      "################",
      "########l#######",
      "################",
      "################",
      "################",
      "##########d#####",
      "################",
      "################",
      "################"
    ],
    [
      "##000##oo##000##",
      "#M kkX2M X2M  X#",
      "0N kk 2N  2N   0",
      "0s  u 2s u2s  u0",
      "0O  k 2O A2O A 0",
      "#22t2222t222t22#",
      "# kkkkkkkkkkkk #",
      "RX&  s 0 0 s  Xq",
      "R     C0l0C    q",
      "#X  O  000  O X#",
      "# kkkkkkkkkkkk #",
      "022t2222t222t220",
      "0M AAX2M X2M  X0",
      "0N AA 2N  2N   0",
      "#s  u 2s u2s O #",
      "##000##qq##000##"
    ],
    [
      "##aqa##qq##qqa##",
      "#s    2   2s   #",
      "q  %  2   2  % a",
      "'s    2   2s   q",
      "q     2   2    a",
      "#22z2222z222z22#",
      "#              #",
      "q Y    0 0    Yo",
      "q      0l0     o",
      "# Y    000    Y#",
      "#              #",
      "a22z2222z222z22q",
      "qs    2   2s   ,",
      "a  %  2   2  % q",
      "#s    2   2s   #",
      "##aqq##HH##aqa##"
    ],
    [
      "##aEa##??##E?a##",
      "#  \\  2   2    #",
      "a     2   2 \\  a",
      "[     2   2    ,",
      "a  \\  2   2    a",
      "#22222222222222#",
      "#              #",
      "'      0 0     ,",
      "'  \\   0l0   \\ ,",
      "#      000     #",
      "#              #",
      "a22222222222222a",
      "'     2   2 \\  ]",
      "a  \\  2   2    a",
      "#     2   2    #",
      "##a;H##qq##aHa##"
    ],
    [
      "##000##qq##000##",
      "# n   q   q  n #",
      "0     q   q    0",
      "0qqqqqqqqqqqqqq0",
      "0 n   q   q  n 0",
      "#     q   q    #",
      "#  E        E  #",
      "o  n   0 0  n  q",
      "oqqqqqq0l0qqqqqq",
      "#  n   000  n  #",
      "#  E        E  #",
      "0     q   q    0",
      "0qqqqqqqqqqqqqq0",
      "0 n   q   q  n 0",
      "#     q   q    #",
      "##000##oo##000##"
    ],
    [
      "################",
      "################",
      "################",
      "################",
      "################",
      "################",
      "################",
      "################",
      "########l#######",
      "################",
      "################",
      "################",
      "################",
      "################",
      "################",
      "################"
    ]
  ]
}
