{
  "xsize": 16,
  "zsize": 16,
  "slices": [
    [
      "0000000000000000",
      "0##############0",
      "0##############0",
      "0##############0",
      "0##############0",
      "0##############0",
      "0##############0",
      "0##############0",
      "0##############0",
      "0##############0",
      "0##############0",
      "0##############0",
      "0##############0",
      "0##    >#######0",
      "0##    >#######0",
      "0000000000000000"
    ],
    [
      "00############00",
      "0        #s   C0",
      "# kkkk   # ... #",
      "# .k.k.    ... #",
      "# kkkk   # ... #",
      "# kkkk   #     #",
      "# .k.k.  ### ###",
      "#        mmmmm #",
      "#5       m.m.ms#",
      "#F. . .  mmmmms#",
      "#O&      m.m.ms#",
      "#      }      s#",
      "#  3333        #",
      "# >            #",
      "0 >            0",
      "00############00"
    ],
    [
      "00aaaa#aa#aaaa00",
      "0        a     0",
      "a        a --- a",
      "a - - -    --- a",
      "a        a --- a",
      "a        a     a",
      "# - - -  #aa aa#",
      "a              a",
      "a         - -  a",
      "# - - -       s#",
      "a         - -  a",
      "a              a",
      "a              a",
      "a  >           a",
      "0  >           0",
      "00aaaa#aa#aaaa00"
    ],
    [
      "00aaaa#aa#aaaa00",
      "0    %   a     0",
      "a        a     a",
      "a              a",
      "a        a     a",
      "a        a     a",
      "#        #aa aa#",
      "a              a",
      "a              a",
      "#              #",
      "a              a",
      "a       %      a",
      "a              a",
      "a   >          a",
      "0   >          0",
      "00aaaa#aa#aaaa00"
    ],
    [
      "00############00",
      "0        #     0",
      "#        #     #",
      "#  n   n #  n  #",
      "#        #     #",
      "#        #     #",
      "#        #######",
      "#              #",
      "#  n   n       #",
      "#          n   #",
      "#              #",
      "#              #",
      "#   n          #",
      "#    >         #",
      "0    >         0",
      "00############00"
    ],
    [
      "8JJJJJJJJJJJJJJ8",
      "I##############U",
      "I##############U",
      "I##############U",
      "I##############U",
      "I##############U",
      "I##############U",
      "I##############U",
      "I##############U",
      "I##############U",
      "I##############U",
      "I##############U",
      "I##############U",
      "I##   >########U",
      "I##   >########U",
      "8PPPPPPPPPPPPPP8"
    ]
  ]
}
