{
  "xsize": 16,
  "zsize": 16,
  "slices": [
    [
      "0000000000000000",
      "0####800008####0",
      "0####0fifi0####0",
      "0####0ifif0####0",
      "0####0fifi0####0",
      "0####0ifif0####0",
      "0####0fifi0####0",
      "0####0ifif0####0",
      "0####800008####0",
      "0##############0",
      "0##############0",
      "0##############0",
      "0##############0",
      "0##    >#######0",
      "0##    >#######0",
      "0000000000000000"
    ],
    [
      "00aaaa   #aaaa00",
      "0   D      D   0",
      "a   5      5 L a",
      "a            L a",
      "a              a",
      "a    VVVVV     a",
      "#   5000005    #",
      "a    00000     a",
      "a    ^^^^      a",
      "#222  22222 222#",
      "as      2 O  & a",
      "asF.. C       sa",
      "a  3333       sa",
      "a >         1  a",
      "0 >            0",
      "00aaaa#aa#aaaa00"
    ],
    [
      "00aaaa   #aaaa00",
      "0   p      p   0",
      "a              a",
      "a              a",
      "a              a",
      "a              a",
      "#    66666     #",
      "a     &kO      a",
      "a              a",
      "#222  22222 222#",
      "a       2      a",
      "as --          a",
      "a         %    a",
      "a  >           a",
      "0  >           0",
      "00aaaa#aa#aaaa00"
    ],
    [
      "00aaaa   #aaaa00",
      "0              0",
      "a              a",
      "a %            a",
      "a            % a",
      "a              a",
      "#              #",
      "a              a",
      "a              a",
      "#222  22222 222#",
      "a       2      a",
      "a              a",
      "a              a",
      "a   >          a",
      "0   >          0",
      "00aaaa#aa#aaaa00"
    ],
    [
      "0088888888888800",
      "0              0",
      "8              8",
      "8      n     n 8",
      "8              8",
      "8              8",
      "8  n        n  8",
      "8              8",
      "8              8",
      "8222222n22222228",
      "8       2   n  8",
      "8  n    2      8",
      "8       2      8",
      "8    >         8",
      "0    >         0",
      "0088888888888800"
    ],
    [
      "8JJJJJJJJJJJJJJ8",
      "I##############U",
      "I##############U",
      "I##############U",
      "I##############U",
      "I##############U",
      "I##############U",
      "I##############U",
      "I##############U",
      "I##############U",
      "I##############U",
      "I##############U",
      "I##############U",
      "I##   >########U",
      "I##   >########U",
      "8PPPPPPPPPPPPPP8"
    ]
  ]
}
