{
  "xsize": 16,
  "zsize": 16,
  "slices": [
    [
      "############m###",
      "#   mmmmmmmm   #",
      "#   m...     r #",
      "mmmmmD  q      #",
      "#      D .mqmmq#",
      "#q    D   mqI:q#",
      "# q    GD mqmmU#",
      "#    ## ##m    #",
      "#P   #   #mqmmq#",
      "#  q # l #mqI:qm",
      "#    # # #mqmmq#",
      "#C s #####     #",
      "# q   m r      #",
      "# & r m       &#",
      "#     mm       #",
      "######m###rrrr##"
    ],
    [
      "____________m___",
      "      H        _",
      "               _",
      "     p  m:     _",
      "_      p  Hq66q_",
      "_|    p    6JJ6_",
      "_ m:   Kp  q66q_",
      "_    ## ## '   _",
      "_    #   # q66q_",
      "_  m:#   # 6JJ6m",
      "_    # # #Hq66q_",
      "_    #####     _",
      "_ m\\         \\ _",
      "_     H        _",
      "_              _",
      "______m___    __"
    ],
    [
      "                ",
      "                ",
      "                ",
      "        m       ",
      "                ",
      "            |   ",
      "  m             ",
      "     #?#?#      ",
      "     # j #      ",
      "   m #   #  |   ",
      "     # # #      ",
      "     #####      ",
      "  m             ",
      "                ",
      "                ",
      "                "
    ],
    [
      "                ",
      "                ",
      "                ",
      "        H       ",
      "                ",
      "                ",
      "  H             ",
      "     #####      ",
      "     #####      ",
      "   H #####      ",
      "     #####      ",
      "     #####      ",
      "  H             ",
      "                ",
      "                ",
      "                "
    ],
    [
      "                ",
      "                ",
      "                ",
      "                ",
      "                ",
      "                ",
      "                ",
      "     _____      ",
      "                ",
      "      |         ",
      "                ",
      "     _____      ",
      "                ",
      "                ",
      "                ",
      "                "
    ],
    [
      "                ",
      "                ",
      "                ",
      "                ",
      "                ",
      "                ",
      "                ",
      "                ",
      "                ",
      "                ",
      "                ",
      "                ",
      "                ",
      "                ",
      "                ",
      "                "
    ]
  ]
}
