{
  "xsize": 16,
  "zsize": 16,
  "slices": [
    [
      "################",
      "################",
      "###dd#####d#####",
      "##ddd###########",
      "################",
      "########dd##d###",
      "################",
      "###d############",
      "########l#######",
      "################",
      "################",
      "#####dd#####dd##",
      "################",
      "####d######d####",
      "################",
      "################"
    ],
    [
      "##0}0##}}##0u0##",
      "#}v  8   v}  8 #",
      "0 } \\   8   }  0",
      "u8  v  }}   v 8}",
      "0  }    \\    } 0",
      "#22} }  } }  22#",
      "# }        \\  }#",
      "}} O   8 8  O  q",
      "}   \\  8l8   1 q",
      "#}  v  888  }  #",
      "#  \\      }    #",
      "022  }  } }  220",
      "}} &   \\   v  }u",
      "0 v  }     \\  80",
      "#8  }   v}   } #",
      "##0u0##}}##0}0##"
    ],
    [
      "##a a##qq##a}a##",
      "# \\      \\    8#",
      "a              a",
      "}  \\     \\      ",
      "a     %        a",
      "#22  }   }   22#",
      "# \\          \\ #",
      "q      8 8     o",
      "q  \\   8l8   \\ o",
      "#      888     #",
      "#    \\     \\   #",
      "a22  }   }   22a",
      "  \\         \\  }",
      "a              a",
      "#   \\     \\    #",
      "##a}a##qq##a a##"
    ],
    [
      "##a a##{{##aaa##",
      "#  {      {    #",
      "a              a",
      "a   \\    \\      ",
      "a              a",
      "#2}  }  }   }2 #",
      "#  \\        \\  #",
      "{      8 8     ,",
      "{      8l8     ,",
      "#      888     #",
      "#     \\   \\    #",
      "a2}   }  }   }2a",
      "   {      {    a",
      "a              a",
      "#  \\        \\  #",
      "##aaa##{{##a a##"
    ],
    [
      "##000##qq##000##",
      "#qq}  \\  }qq  }#",
      "0        }     0",
      "0 {       {    0",
      "0}  }    }   } 0",
      "# qq}      }qq #",
      "#     n        #",
      "q  }   8 8   } q",
      "qqq}   8l8   }qq",
      "#      888  j  #",
      "#  }        }  #",
      "0q}         }q 0",
      "0              0",
      "0  {   }    {  0",
      "#}    }    }   #",
      "##000##qq##000##"
    ],
    [
      "################",
      "################",
      "################",
      "################",
      "####dd######d###",
      "################",
      "#######d########",
      "################",
      "########l#######",
      "################",
      "################",
      "###d#######dd###",
      "################",
      "################",
      "################",
      "################"
    ]
  ]
}
