{
  "xsize": 16,
  "zsize": 16,
  "slices": [
    [
      "eeeeeeeeeeeeeeee",
      "effffffffffffffe",
      "efffffffffff}ffe",
      "efff}ffffffffffe",
      "effffffffffffffe",
      "effffffffff}fffe",
      "effffffffffffffe",
      "effffffffffffffe",
      "eff}fffflffffffe",
      "effffffffffffffe",
      "effffffffffffffe",
      "effffffff}fffffe",
      "ef}ffffffffffffe",
      "efffff}ffffffffe",
      "effffffffffffffe",
      "eeeeeeeeeeeeeeee"
    ],
    [
      "eeeeeeeeeeeeeeee",
      "ecccq  X   s&sse",
      "equuq  \\   sssse",
      "eqWWq      s&sse",
      "eqqqq  }   sssse",
      "eR      i     Re",
      "e  }        &  e",
      "ecc    8 8   sse",
      "ecc    8l8  C se",
      "egg    888   sse",
      "e&      }      e",
      "e:::::  }  ::::e",
      "e:&  :     : &:e",
      "e: ss:  4  :ss:e",
      "e:::::  i  ::::e",
      "eeeeeeeeeeeeeeee"
    ],
    [
      "eeeeeeeeeeeeeeee",
      "ecEEq      sssse",
      "eq  q  %   s  se",
      "eq  q      sssse",
      "eqqqq      s  se",
      "e              e",
      "e %          % e",
      "egg    8 8   sse",
      "e      8l8    se",
      "e      888   sse",
      "e        %     e",
      "e:::::     ::::e",
      "e:   :     :  :e",
      "e:   :  %  :  :e",
      "e:::::     ::::e",
      "eeeeeeeeeeeeeeee"
    ],
    [
      "eeeeeeeeeeeeeeee",
      "e{  {      %   e",
      "e          \\   e",
      "e{  {          e",
      "e     %      % e",
      "e  \\        \\  e",
      "e              e",
      "e      8 8     e",
      "e  \\   8l8   \\ e",
      "e      888     e",
      "e   %       %  e",
      "e{         {   e",
      "e      \\       e",
      "e  \\        \\  e",
      "e{         {   e",
      "eeeeeeeeeeeeeeee"
    ],
    [
      "eeeeeeeeeeeeeeee",
      "eqqqq      ooooe",
      "eq  q   n  o  oe",
      "eq  q      o  oe",
      "eqqqq      ooooe",
      "eqqqqqqqqqqqqqqe",
      "e  n        n  e",
      "e      8 8     e",
      "eqqqqq 8l8 qqqqe",
      "e      888     e",
      "e  j        j  e",
      "eoooo      ooooe",
      "eo  o   {  o  oe",
      "eo  o      o  oe",
      "eoooo      ooooe",
      "eeeeeeeeeeeeeeee"
    ],
    [
      "################",
      "################",
      "################",
      "################",
      "###8########8###",
      "################",
      "################",
      "################",
      "########l#######",
      "################",
      "################",
      "###8########8###",
      "################",
      "################",
      "################",
      "################"
    ]
  ]
}
