{
  "xsize": 16,
  "zsize": 16,
  "slices": [
    [
      "#$$#$$#$$#$$m$$#",
      "$7777e7777e7777$",
      "$7777e7777e7777$",
      "m7777e7777e7777#",
      "$7777e7777e7777$",
      "$7777e7777e7777$",
      "#eeeeeeeeeeeeee#",
      "$oooooooooooooo$",
      "$oooooooooooooo$",
      "#eeeeeeleeeeeeem",
      "$7777e7777e7777$",
      "$7777e7777e7777$",
      "#7777e7777e7777#",
      "$7777e7777e7777$",
      "$7777e7777e7777$",
      "#$$#$$m$$#$$#$$#"
    ],
    [
      "#mN####Nm###m###",
      "#  L 2  , 2 C  #",
      "#]5  2  5]2]5  #",
      "m[   2   [2[   #",
      "#,   2M  ,2,   #",
      "#  ^s2s^  2  ^s#",
      "#2 2222 2222 22#",
      "U   r          #",
      "m          r   #",
      "#2 2222l2 222 2m",
      "#    2222 2    #",
      "#  5]2    2  5]#",
      "#   [25]  2   [#",
      "#   ,2 [  2   ,N",
      "#s&  2   s2s^O m",
      "######m###mN####"
    ],
    [
      "#q:#aa#:q#aaHaa#",
      "a    2    2    a",
      "a  % 2    2    a",
      "H    2    2    #",
      "a    2    2    a",
      "a    2    2  % a",
      "#2 2222 2222 22#",
      "q              a",
      "q              a",
      "#2 22T2l2 222 2H",
      "a    2222 2   %a",
      "a    2  % 2    a",
      "#    2    2    #",
      "a%   2    2    :",
      "a    2    2    q",
      "#aa#aaHaa#q:#aa#"
    ],
    [
      "#aa#aa#HH#aamaa#",
      "a    2    2    a",
      "a    2    2    a",
      "m H  2\\H  2 H  #",
      "a    2    2    a",
      "a    2    2    a",
      "#22222222222222#",
      ":          n   a",
      ":   n          a",
      "#222222l2222222m",
      "a    2222 2    a",
      "a    2    2    a",
      "# H  2 H  2 H  #",
      "a    2    2 \\  H",
      "a    2    2    H",
      "#aa#aamaa#aa#aa#"
    ],
    [
      "############m###",
      "#    2    2    #",
      "#    2    2    #",
      "m m  2 m  2 m  #",
      "# m  2 m  2 m  #",
      "# m  2 m  2 m  :",
      "#2m2222m2222m22:",
      "#mmmmmmmmmm{mmm:",
      "#   {          #",
      "#2m2222l2222m22m",
      "# m  22m2 2 m  #",
      "m m  2 m  2 m  #",
      "m m  2 m  2 m  #",
      "#    2    2    #",
      "#    2    2    #",
      "######m#########"
    ],
    [
      "############m###",
      "################",
      "################",
      "m###############",
      "################",
      "################",
      "################",
      "#mmmmmmmmmmmmmm#",
      "################",
      "#######l#######m",
      "################",
      "################",
      "################",
      "################",
      "################",
      "######m#########"
    ]
  ]
}
