{
  "xsize": 16,
  "zsize": 16,
  "slices": [
    [
      "0000000000000000",
      "0##############0",
      "0##############0",
      "0##############0",
      "0##############0",
      "0##############0",
      "0##############0",
      "0##############0",
      "0##############0",
      "0##############0",
      "0##############0",
      "0##############0",
      "0##############0",
      "0##    >#######0",
      "0##    >#######0",
      "0000000000000000"
    ],
    [
      "00############00",
      "0s   O2mm2O   s0",
      "# ..   mm   .. #",
      "#     2mm2     #",
      "#222222mm222222#",
      "#L    2mm2    s#",
      "#L..   mm  .. s#",
      "#    C2mm2&    #",
      "#222222mm222222#",
      "#F     mm C    #",
      "# &  12mm2  ..F#",
      "#           O  #",
      "#  3333        #",
      "# >            #",
      "0 >            0",
      "00############00"
    ],
    [
      "00#aa#aa#aa#aa00",
      "0     2  2     0",
      "# --        -- #",
      "a     2  2     a",
      "a222222  222222a",
      "#     2  2     #",
      "a --       -- sa",
      "a     2  2     a",
      "#222222  222222#",
      "a  %           a",
      "a     2  2  -- a",
      "#              #",
      "a              a",
      "a  >           a",
      "0  >           0",
      "00#aa#aa#aa#aa00"
    ],
    [
      "00#aa#aa#aa#aa00",
      "0     2  2     0",
      "#              #",
      "a     2  2     a",
      "a222222  222222a",
      "#   % 2  2     #",
      "a              a",
      "a     2  2     a",
      "#222222  222222#",
      "a          %   a",
      "a     2  2     a",
      "#              #",
      "a              a",
      "a   >          a",
      "0   >          0",
      "00#aa#aa#aa#aa00"
    ],
    [
      "00############00",
      "0     2  2     0",
      "#  n  2n 2  n  #",
      "#     2  2     #",
      "#222222  222222#",
      "#     2  2     #",
      "#     2n 2     #",
      "#     2  2     #",
      "#222222  222222#",
      "#     2  2     #",
      "#     2n 2     #",
      "#              #",
      "#          n   #",
      "#    >         #",
      "0    >         0",
      "00############00"
    ],
    [
      "8JJJJJJJJJJJJJJ8",
      "I##############U",
      "I##############U",
      "I##############U",
      "I##############U",
      "I##############U",
      "I##############U",
      "I##############U",
      "I##############U",
      "I##############U",
      "I##############U",
      "I##############U",
      "I##############U",
      "I##   >########U",
      "I##   >########U",
      "8PPPPPPPPPPPPPP8"
    ]
  ]
}
