{
  "xsize": 16,
  "zsize": 16,
  "slices": [
    [
      "##   ######   ##",
      "#eeeeeeeeeeeeee#",
      " #eeeeeeeeeeee# ",
      " #eeeeeeeeeeee# ",
      " #eeeeeeeeeeee# ",
      "#eeeeeeeeeeeeee#",
      "#eeeeeeeeeeeeee#",
      "#eeeeeeeeeeeeee#",
      "#eeeeeeeeeeeeee#",
      "#eeeeeeleeeeeee#",
      "#eeeeeeeeeeeeee#",
      " #eeeeeeeeeeee# ",
      " #eeeeeeeeeeee# ",
      " #eeeeeeeeeeee# ",
      "#eeeeeeeeeeeeee#",
      "##   ######   ##"
    ],
    [
      "##qmq######   ##",
      "##aaa#    #aaa##",
      " a,        LL,a ",
      " a 555    555 a ",
      " a ^ ^    ^ ^ a ",
      "##???2    2???##",
      "#s C  7777   Os#",
      "#s55  7777  55s#",
      "# ^        r ^ #",
      "# O   2l2   &  #",
      "##    222     ##",
      " a  V      V  am",
      " a 555r   555 am",
      " a,      r   ,am",
      "##aaa#    #aaa##",
      "##   ######qmq##"
    ],
    [
      "##:0:######:::##",
      "##aaa#    #aaa##",
      "qa         %  a ",
      "ma            a ",
      "qa%           a ",
      "##???2    2???##",
      "#              #",
      "#              #",
      "#   %          #",
      "#    T2l2T     #",
      "##    222     ##",
      " a           %aq",
      " a            a:",
      " a   %        aq",
      "##aaa#    #aaa##",
      "##   ######:J:##"
    ],
    [
      "##qmq:####:mmm##",
      "##aaa#    #aaa##",
      "qa            a ",
      ":a    \\       a ",
      "qa            a ",
      ":#            #:",
      "#   H      H   #",
      "#              #",
      "# n          n #",
      "#     2l2      #",
      ":#    222     #:",
      " a            a ",
      " a            am",
      " a        \\   a ",
      "##aaa#    #aaa##",
      "##   :####:qmq##"
    ],
    [
      "##   ######   ##",
      "##aaa#    #aaa##",
      "5a     mm     a ",
      "5a n   m    n a ",
      "5a     m      a ",
      "##            ##",
      "#qmmmmmmmmmmmmq#",
      "#              #",
      "# {          { #",
      "#     2l2      #",
      "##    222     ##",
      " a     mm     a ",
      " a n   m    n am",
      " a            a ",
      "##aaa#    #aaa##",
      "##   ######   ##"
    ],
    [
      "##   ######   ##",
      "################",
      " ############## ",
      " ############## ",
      " ############## ",
      "################",
      "#qmmmmmmmmmmmmq#",
      "################",
      "################",
      "#######l########",
      "################",
      " ############## ",
      " ############## ",
      " ############## ",
      "################",
      "##   ######   ##"
    ]
  ]
}
