{
  "xsize": 16,
  "zsize": 16,
  "slices": [
    [
      "################",
      "################",
      "################",
      "################",
      "################",
      "###0########0###",
      "################",
      "################",
      "################",
      "#######l########",
      "###0########0###",
      "################",
      "################",
      "################",
      "################",
      "################"
    ],
    [
      "##___######___##",
      "######qqqq######",
      "_#qEEq   qEEq #_",
      "_#q  q   q  q #u",
      "_#qqqq   qqqq #_",
      "##0        0  ##",
      "#cc  ::::::  cc#",
      "#cc  :&  &:  cc#",
      "#gg  ::::::  gg#",
      "#u     l     u #",
      "##R   ###   R ##",
      "_#qEEq   qEEq #_",
      "u#q  q   q  q #_",
      "_#qqqq   qqqq #_",
      "######o  o######",
      "##___######___##"
    ],
    [
      "##q q######RRR##",
      "##aaa#    #aaa##",
      "qaqEEq   qEEq aq",
      " aq  q   q  q aq",
      "qaqqqq   qqqq aq",
      "##            ##",
      "#gg  ::::::  gg#",
      "#    :    :    #",
      "#    ::::::    #",
      "#      l       #",
      "##    ###     ##",
      "qaqEEq   qEEq aq",
      "qaq  q   q  q a ",
      "qaqqqq   qqqq aq",
      "##aaa#    #aaa##",
      "##RRR######q q##"
    ],
    [
      "##q?q######q?q##",
      "##aaa#    #aaa##",
      "qaoooo   oooo aq",
      "[ao??o   o??o a]",
      "qaoooo   oooo aq",
      "##  {      {  ##",
      "#              #",
      "#  {        {  #",
      "#              #",
      "#      l       #",
      "##    ###     ##",
      "qaoooo   oooo aq",
      "[ao??o   o??o a]",
      "qaoooo   oooo aq",
      "##aaa#    #aaa##",
      "##q;q######q;q##"
    ],
    [
      "##qqq######EEE##",
      "##aaa#qqqq#aaa##",
      "qaQQQQ   QQQQ a,",
      "qaqqqqqqqqqqqqa,",
      "qaQQQQ   QQQQ a,",
      "##  n      n  ##",
      "#qqqqqqqqqqqqqq#",
      "#  n        n  #",
      "#qqqqqqqqqqqqqq#",
      "#      l       #",
      "##{   ###   { ##",
      "'aQQQQ   QQQQ aq",
      "'aqqqqqqqqqqqqaq",
      "'aQQQQ   QQQQ aq",
      "##aaa#qqqq#aaa##",
      "##HHH######qqq##"
    ],
    [
      "##===######===##",
      "################",
      "=##############=",
      "=##############=",
      "=##############=",
      "################",
      "################",
      "################",
      "################",
      "#######l########",
      "################",
      "=##############=",
      "=##############=",
      "=##############=",
      "################",
      "##===######===##"
    ]
  ]
}
