{
  "xsize": 16,
  "zsize": 16,
  "slices": [
    [
      "#$$#$$#$$#$$m$$#",
      "$oooooooooooooo$",
      "$o777777777777o$",
      "mo777777777777o#",
      "$o777777777777o$",
      "$o777777777777o$",
      "#o777777777777o#",
      "$oooooooooooooo$",
      "$oooooooooooooo$",
      "#eeeeeeleeeeeeem",
      "$eeeeeeeeeeeeee$",
      "$eeeeeeeeeeeeee$",
      "#eeeeeeeeeeeeee#",
      "$eeeeeeeeeeeeee$",
      "$eeeeeeeeeeeeee$",
      "#$$#$$m$$#$$#$$#"
    ],
    [
      "####Nm####mNm###",
      "# VV ,   L VV  U",
      "# 55       55  m",
      "m ^^  VV   ^^  #",
      "#, r  55      ,#",
      "# VV  ^^   VV  #",
      "# 55       55  #",
      "# ^^    r  ^^  #",
      "#   O     ,  & #",
      "#     2l2      m",
      "#     222      #",
      "#22 2222 2222 2#",
      "#3333 2^^ 2VV M#",
      "mC P s233 255  #",
      "NFFs& 2& s2^^ ,#",
      "####Nmm#########"
    ],
    [
      "#aa#:q#aa#q:Haa#",
      "a     %        q",
      "a              q",
      "H             %#",
      "a              a",
      "a              a",
      "#            % #",
      "a              a",
      "a %            a",
      "#    T2l2T     H",
      "a     222      a",
      "a22 2?22 22?2 2a",
      "#5555 2  %2    #",
      "q     255 2    a",
      ": 5   2   2    a",
      "#aa#:qHaa#aa#aa#"
    ],
    [
      "#aa#HH#aa#aamaa#",
      "a              :",
      "a  n        n  :",
      "m              #",
      "a  H        H  a",
      "a              a",
      "#              #",
      "a    \\         a",
      "aN             a",
      "#     2l2     Nm",
      "a     222      a",
      "a2222?22222?222a",
      "#  H  2   2 H  #",
      "a     2   2    a",
      "a     2   \\    a",
      "#aa#HHmaa#aa#aa#"
    ],
    [
      "############m###",
      "#              #",
      "#  {        {  #",
      "m              #",
      "#mmmmmmmmmmmmmm#",
      "#      m       #",
      "#  n   m    n  #",
      "#      m       #",
      "#      m       #",
      "#     2l2      m",
      "#     222      #",
      "#22222222222222m",
      "#mmmmmmmmmmmmmmm",
      "# j   2 n 2    #",
      "#     2   2    #",
      "######m###::#::#"
    ],
    [
      "############m###",
      "################",
      "################",
      "m###############",
      "#mmmmmmmmmmmmmm#",
      "################",
      "################",
      "################",
      "################",
      "#######l#######m",
      "################",
      "################",
      "#mmmmmmmmmmmmmm#",
      "################",
      "################",
      "######m#########"
    ]
  ]
}
