{
  "xsize": 16,
  "zsize": 16,
  "slices": [
    [
      "##   ######   ##",
      "#eeeeeeeeeeeeee#",
      " #eeeeeeeeeeee# ",
      " #eeeeeeeeeeee# ",
      " #eeeeeeeeeeee# ",
      "#eeeeeeeeeeeeee#",
      "#eeeeeeeeeeeeee#",
      "#eeeeeeeeeeeeee#",
      "#eeeeeeeeeeeeee#",
      "#eeeeeeleeeeeee#",
      "#eeeeeeeeeeeeee#",
      " #eeeeeeeeeeee# ",
      " #eeeeeeeeeeee# ",
      " #eeeeeeeeeeee# ",
      "#eeeeeeeeeeeeee#",
      "##   ######   ##"
    ],
    [
      "##   ######  q##",
      "##aaa#    #aaa##",
      " as] s2 FF5& sa ",
      " a [  2       a ",
      " a7777     r  a ",
      "##77<72  55  L##",
      "# ,755 r ^^ C  #",
      "#2 2222222222 2#",
      "#              #",
      "#L&  r2l22 O  s#",
      "##    22227777##",
      "maF    r  777,a ",
      "ma 55   C2  ] a ",
      "ma ^^ ,  2s [ a ",
      "##aaa#    #aaa##",
      "##qmq###### r ##"
    ],
    [
      "##qmq:####: qm##",
      "##aaa#    #aaa##",
      " a    2       a:",
      " a%   2     % a:",
      " a           %a:",
      ":#    2       #:",
      "#              #",
      "#2 2222222222 2#",
      "#              #",
      "#  %  2l22     #",
      ":#    2222%   #:",
      "qa    %       a ",
      ":a       2    a ",
      "qa       2    a ",
      "##aaa#    #aaa##",
      "##:0::####:   ##"
    ],
    [
      "##q:q######qmq##",
      "##aaa#    #aaa##",
      " a    2       am",
      " aH   2  \\    am",
      " a    2       am",
      "##    2n      ##",
      "#              #",
      "#222q:q2222q:q2#",
      "#              #",
      "#     2l22     #",
      "##    2222    ##",
      " a   \\   2    a ",
      "ma       2   Ha ",
      " a       2    a ",
      "##aaa#    #aaa##",
      "##qmq###### q ##"
    ],
    [
      "##555###### 5 ##",
      "##aaa#    #aaa##",
      " a    2       a ",
      " a n  2    n  a ",
      " a    2       a ",
      "##    2{      ##",
      "#              #",
      "#2222H222222H22#",
      "# mmmmmmmmmmmm #",
      "#     2l22     #",
      "##    2222    ##",
      " a       2  j a ",
      "ma  n    2    a ",
      " a       2    a ",
      "##aaa#    #aaa##",
      "##   ###### m ##"
    ],
    [
      "##   ######   ##",
      "################",
      " ############## ",
      " ############## ",
      " ############## ",
      "################",
      "################",
      "################",
      "##mmmmmmmmmmmm##",
      "#######l########",
      "################",
      " ############## ",
      " ############## ",
      " ############## ",
      "################",
      "##   ######   ##"
    ]
  ]
}
