{
  "xsize": 16,
  "zsize": 16,
  "slices": [
    [
      "0000000000000000",
      "0##############0",
      "0##############0",
      "0##############0",
      "0#########}}}##0",
      "0########}}}}}#0",
      "0#########}}}##0",
      "0##############0",
      "0##############0",
      "0##############0",
      "0##############0",
      "0##############0",
      "0##############0",
      "0##    >#######0",
      "0##    >#######0",
      "0000000000000000"
    ],
    [
      "00############00",
      "0   Oe         0",
      "# .} e         #",
      "#s   e         #",
      "#         }r6} e",
      "#          }r  e",
      "#    }   r 4}  e",
      "#F   e   5}r r e",
      "#   Ce         e",
      "# &1           e",
      "#  }           #",
      "#              #",
      "#  3333        #",
      "# >            #",
      "0 >            0",
      "00############00"
    ],
    [
      "00aaaa#aa#aaaa00",
      "0    e   %     0",
      "a -  e         a",
      "a    e         a",
      "a          r   e",
      "a         } r  e",
      "# %  e   r     e",
      "a    e     r r e",
      "a    e         e",
      "#              e",
      "a     \\     %  a",
      "a           {  a",
      "a              a",
      "a  >           a",
      "0  >           0",
      "00aaaa#aa#aaaa00"
    ],
    [
      "00aaaa#aa#aaaa00",
      "0 %  e         0",
      "a    e%      % a",
      "a    e  \\      a",
      "a              e",
      "a              e",
      "#    e         e",
      "a    e         e",
      "a    e         e",
      "#      %  \\    e",
      "a              a",
      "a           { %a",
      "a%             a",
      "a   >          a",
      "0   >          0",
      "00aaaa#aa#aaaa00"
    ],
    [
      "00############00",
      "0    e         0",
      "#    e         #",
      "#    e         #",
      "#    e         #",
      "#    e         #",
      "#   je         e",
      "#    e         e",
      "#    e         #",
      "#              #",
      "#              #",
      "#              #",
      "#              #",
      "#    >         #",
      "0    >         0",
      "00############00"
    ],
    [
      "8JJJJJJJJJJJJJJ8",
      "I##############U",
      "I##############U",
      "I########     #U",
      "I########     #U",
      "I#######e     eU",
      "I########     #U",
      "I########     #U",
      "I##############U",
      "I##############U",
      "I##############U",
      "I##############U",
      "I##############U",
      "I##   >########U",
      "I##   >########U",
      "8PPPPPPPPPPPPPP8"
    ]
  ]
}
