{
  "xsize": 16,
  "zsize": 16,
  "slices": [
    [
      "################",
      "################",
      "##00########00##",
      "##0##########0##",
      "################",
      "################",
      "####0######0####",
      "################",
      "################",
      "#######l########",
      "####0######0####",
      "################",
      "##0##########0##",
      "##00########00##",
      "################",
      "################"
    ],
    [
      "##_u_##  ##___##",
      "######k66k######",
      "_#0D0      0D0#_",
      "u#>kkkkkkkkkk<#u",
      "_#>kkkkkkkkkk<#_",
      "##XkkkkkkkkkkX##",
      "#X 555555555  X#",
      "#ssO  <  >  Oss#",
      "# kkkkkkkkkkkk #",
      "#qq    l    qqq#",
      "##X   ###    X##",
      "_#>kkkkkkkkkk<#_",
      "u#>kkkk55kkkk<#u",
      "_#qq        qq#_",
      "######k66k######",
      "##___##  ##_u_##"
    ],
    [
      "##qqq##  ##o?o##",
      "##aaa#    #aaa##",
      "oa p        p a,",
      "'a  %       % aq",
      "oa            a,",
      "##            ##",
      "#  `````````   #",
      "#ss         ss #",
      "#   %       %  #",
      "#      l       #",
      "##    ###     ##",
      "'a            ao",
      "qa     %      a,",
      "'agE        Egao",
      "##aaa#    #aaa##",
      "##o;o##  ##qqq##"
    ],
    [
      "##q?q######oEo##",
      "##aaa#    #aaa##",
      "oa            aQ",
      "[a   \\      \\ a]",
      "oa            aQ",
      "##            ##",
      "#              #",
      "#    %     %   #",
      "#              #",
      "#      l       #",
      "##    ###     ##",
      "Qa            ao",
      "[a  \\       \\ a]",
      "Qa            ao",
      "##aaa#    #aaa##",
      "##oHo######q;q##"
    ],
    [
      "##EEE###### { ##",
      "##aaa#    #aaa##",
      "oa  n      n  a ",
      "oa            a ",
      "oa  {      {  a ",
      "##qqqqqqqqqqqq##",
      "# E          E #",
      "#  n        n  #",
      "#              #",
      "#      l       #",
      "##    ###     ##",
      " a  n      n  ao",
      " a            ao",
      " a  {      {  ao",
      "##aaa#    #aaa##",
      "## { ######HHH##"
    ],
    [
      "##===######===##",
      "################",
      "=##############=",
      "=##############=",
      "=##############=",
      "################",
      "################",
      "################",
      "################",
      "#######l########",
      "################",
      "=##############=",
      "=##############=",
      "=##############=",
      "################",
      "##===######===##"
    ]
  ]
}
