{
  "xsize": 16,
  "zsize": 16,
  "slices": [
    [
      "##   ######   ##",
      "#eeeeeeeeeeeeee#",
      " #eeeeeeeeeeee# ",
      " #eeeeeeeeeeee# ",
      " #eeeeeeeeeeee# ",
      "#eeeeeeeeeeeeee#",
      "#eeeeeeeeeeeeee#",
      "#eeeeeeeeeeeeee#",
      "#eeeeeeeeeeeeee#",
      "#eeeeeeleeeeeee#",
      "#eeeeeeeeeeeeee#",
      " #eeeeeeeeeeee# ",
      " #eeeeeeeeeeee# ",
      " #eeeeeeeeeeee# ",
      "#eeeeeeeeeeeeee#",
      "##   ######   ##"
    ],
    [
      "##  q######qmq##",
      "##aaa#    #aaa##",
      ":a55 CO2 , 55&aq",
      "ma V        V am",
      ":as  , 2L    saq",
      "##22 222222 22##",
      "#L7777777r7777s#",
      "#77777777777r77#",
      "#22 22222222 22#",
      "#     2l2      #",
      "##    222     ##",
      " a552 55  2 55a ",
      " a^   ^     ^ a ",
      " asO2r  , 2& sa ",
      "##aaa#    #aaa##",
      "##q:q######   ##"
    ],
    [
      "## qm:####::0:##",
      "##aaa#    #aaa##",
      ":a     2  %   a:",
      "ma            aJ",
      ":a%    2      a:",
      ":#?2 2?22?2 2?#:",
      "#            % #",
      "# %            #",
      "#?2 22?22?22 2?#",
      "#    T2l2      #",
      ":#    222     #:",
      ":a  2     2  %a ",
      ":a   %        a ",
      ":a  2     2   a ",
      "##aaa#    #aaa##",
      "##q:q:####:   ##"
    ],
    [
      "##qmq:####:qmq##",
      "##aaa#    #aaa##",
      ":a \\   2      aq",
      "ma H  H2 H  H am",
      ":a     2      aq",
      ":#?222?22?222?#:",
      "#      n       #",
      "#              #",
      "#?2222?22?2222?#",
      "#     2l2      #",
      ":#    222     #:",
      "ma  2   \\ 2   a ",
      "ma H2 H  H2 H a ",
      "ma  2     2   a ",
      "##aaa#    #aaa##",
      "##q:q:####:   ##"
    ],
    [
      "## 5 ######   ##",
      "##aaa#    #aaa##",
      ":an    2     na ",
      "ma m  m2 m  m a ",
      ":a m  m2 m  m a ",
      "##2m22m22m22m2##",
      "#q m  m{ m  m q#",
      "#mmmmmmmmmmmmmm#",
      "#22222222222222#",
      "#  m  2l2m  m  #",
      "## m  222m  m ##",
      " a m2 m  m2 m a ",
      " a m2 m  m2 m a ",
      " an 2     2  na ",
      "##aaa#    #aaa##",
      "##   ######   ##"
    ],
    [
      "##   ######   ##",
      "################",
      " ############## ",
      " ############## ",
      " ############## ",
      "################",
      "################",
      "#mmmmmmmmmmmmmm#",
      "################",
      "#######l########",
      "################",
      " ############## ",
      " ############## ",
      " ############## ",
      "################",
      "##   ######   ##"
    ]
  ]
}
