{
  "xsize": 16,
  "zsize": 16,
  "slices": [
    [
      "0000000000000000",
      "0######ii######0",
      "0######ii######0",
      "0######ii######0",
      "0######ii######0",
      "0######ii######0",
      "0######ii######0",
      "0######ii######0",
      "0######ii######0",
      "0######ii######0",
      "0######ii######0",
      "0##############0",
      "0##############0",
      "0##    >#######0",
      "0##    >#######0",
      "0000000000000000"
    ],
    [
      "00############00",
      "0      mm} :C  0",
      "#sssss mm s:s&s#",
      "#      mm  :  q#",
      "#sssss mm ss ::#",
      "#      mm   5  #",
      "#sssss mm sssss#",
      "#      mm      #",
      "#sssss mm sssss#",
      "#      mm2    O#",
      "#&s F1..m2qqqF #",
      "#              #",
      "#  3333        #",
      "# >            #",
      "0 >            0",
      "00############00"
    ],
    [
      "00#a##a##a##a#00",
      "0          :   0",
      "#sssss    s:sss#",
      "a          :   a",
      "#sssss    ss ::#",
      "#              #",
      "asssss    sssssa",
      "#              #",
      "#sssss    sssss#",
      "a        2     a",
      "#     -- 2:::  #",
      "#              #",
      "a              a",
      "#  >           #",
      "0  >           0",
      "00#a##a##a##a#00"
    ],
    [
      "00############00",
      "0     %    :   0",
      "#          :   #",
      "#          :   #",
      "#           :::#",
      "#              #",
      "#         %    #",
      "#              #",
      "#              #",
      "#        2     #",
      "#        2 {   #",
      "#              #",
      "#              #",
      "#   >          #",
      "0   >          0",
      "00############00"
    ],
    [
      "00############00",
      "0              0",
      "#      j     j #",
      "#              #",
      "#              #",
      "#      j       #",
      "#              #",
      "#              #",
      "#      j       #",
      "#        2     #",
      "#        2 {   #",
      "#  j     2     #",
      "#           j  #",
      "#    >         #",
      "0    >         0",
      "00############00"
    ],
    [
      "8JJJJJJJJJJJJJJ8",
      "I##############U",
      "I##############U",
      "I##############U",
      "I##############U",
      "I##############U",
      "I##############U",
      "I##############U",
      "I##############U",
      "I##############U",
      "I##############U",
      "I##############U",
      "I##############U",
      "I##   >########U",
      "I##   >########U",
      "8PPPPPPPPPPPPPP8"
    ]
  ]
}
