{
  "xsize": 16,
  "zsize": 16,
  "slices": [
    [
      "################",
      "################",
      "################",
      "################",
      "################",
      "################",
      "################",
      "##0##########0##",
      "########l#######",
      "##0##########0##",
      "################",
      "################",
      "################",
      "################",
      "################",
      "################"
    ],
    [
      "##000##RR##000##",
      "#LLLLLL2sss X s#",
      "0s    s2  M M  0",
      "0s    s2  N N  0",
      "0s  L s2u  X  s0",
      "#222t222222t222#",
      "# mmmmmmmmmmmm #",
      "qL  >m 0 0 m<  o",
      "qL  5m 0l0 m5 Co",
      "#L  >m 000 m<  #",
      "# mmmmmmmmmmmm #",
      "022t22222222t220",
      "0X  s 2 M  M  X0",
      "0&  s 2 N  N  &0",
      "#L  s 2 u  X  s#",
      "##000##qq##000##"
    ],
    [
      "##aqq##qq##qEq##",
      "#LLLLLL2s      #",
      "os    s2       o",
      "qs    s2    %  ,",
      "os    s2       o",
      "#222z222222z222#",
      "#              #",
      "qL  `  0 0 `   ,",
      "qL  `  0l0 `   ,",
      "#L  `  000 `   #",
      "#              #",
      "o22z22222222z22o",
      "'   s 2  %     q",
      "o   s 2        o",
      "#   s 2        #",
      "##qHq##oo##aqq##"
    ],
    [
      "##a?E##EE##a?a##",
      "#  \\   2   \\   #",
      "'      2       a",
      "[  {   2   {   ]",
      "'      2       a",
      "#22222222222222#",
      "#   %      %   #",
      "o      0 0     ]",
      "o  \\   0l0   \\ ]",
      "#      000     #",
      "#   %      %   #",
      "a22222222222222,",
      "[     2        ]",
      "a  {  2    {   ,",
      "#     2        #",
      "##a;a##HH##a;H##"
    ],
    [
      "##000##oo##000##",
      "# n    q    n  #",
      "0qqqqqqqqqqqqqq0",
      "0  E   q   E   0",
      "0      q       0",
      "#      q       #",
      "#  n        n  #",
      "'      0 0     q",
      "'qqqqqq0l0qqqqqq",
      "#      000     #",
      "#  j        j  #",
      "0     q        0",
      "0qqqqqqqqqqqqqq0",
      "0  E  q    E   0",
      "# n   q     n  #",
      "##000##qq##000##"
    ],
    [
      "################",
      "################",
      "################",
      "################",
      "################",
      "################",
      "################",
      "################",
      "########l#######",
      "################",
      "################",
      "################",
      "################",
      "################",
      "################",
      "################"
    ]
  ]
}
