{
  "xsize": 16,
  "zsize": 16,
  "slices": [
    [
      "0000000000000000",
      "0##############0",
      "0##############0",
      "0##############0",
      "0##############0",
      "0##############0",
      "0##############0",
      "0##############0",
      "0##############0",
      "0##############0",
      "0##############0",
      "0##############0",
      "0##############0",
      "0##    >#######0",
      "0##    >#######0",
      "0000000000000000"
    ],
    [
      "8000000000000008",
      "0         888880",
      "0  VVV    888880",
      "0 >777<   888880",
      "0 >787<   888880",
      "0 >777<   888880",
      "0  ^^^  }      0",
      "0555 555   2 220",
      "0 O q  } } 2  F0",
      "0555 555   2&C20",
      "0          22220",
      "2222222  2     0",
      "21O      2     0",
      "2        2     0",
      "2 &      2     0",
      "2222222222000008"
    ],
    [
      "8333333333333338",
      "3          qqqq3",
      "3          qWWq3",
      "3  { {    :qWWq3",
      "3   :      qqqq3",
      "3  { {    F}   3",
      "3              3",
      "3%         2 223",
      "3   :      2 %23",
      "3     %    2  23",
      "3          22223",
      "2222222  2     3",
      "2        2     3",
      "2        2     3",
      "2        2     3",
      "2222222222333338"
    ],
    [
      "8              8",
      "           qqqq ",
      "           qWWq ",
      "          :qWWq ",
      "    :      qqqq ",
      "                ",
      "                ",
      "           2222 ",
      "           2222 ",
      "           2222 ",
      "           2222 ",
      "2222222222      ",
      "2        2      ",
      "2   n    2      ",
      "2        2      ",
      "2222222222     8"
    ],
    [
      "                ",
      "            {   ",
      "                ",
      "                ",
      "    h        {  ",
      "                ",
      "                ",
      "                ",
      "                ",
      "                ",
      "                ",
      "JJJJJJJJJJ      ",
      "2222222222      ",
      "2222222222      ",
      "2222222222      ",
      "2222222222      "
    ],
    [
      "                ",
      "                ",
      "                ",
      "                ",
      "    :           ",
      "                ",
      "                ",
      "                ",
      "                ",
      "                ",
      "                ",
      "                ",
      "                ",
      "                ",
      "                ",
      "                "
    ]
  ]
}
