{
  "xsize": 16,
  "zsize": 16,
  "slices": [
    [
      "#$$#$$#$$#$$m$$#",
      "$eeeeeeeeeeeeee$",
      "$eeeeeeeeeeeeee$",
      "meeeeeeeeeeeeee#",
      "$eeeeeeeeeeeeee$",
      "$eeeeeeeeeeeeee$",
      "#eeeeeeeeeeeeee#",
      "$eeeeeeeeeeeeee$",
      "$eeeeeeeeeeeeee$",
      "#eeeeeeleeeeeeem",
      "$eeeeeeeeeeeeee$",
      "$ooooeeeeeooooo$",
      "#ooooeeeeeooooo#",
      "$ooooeeeeeooooo$",
      "$ooooeeeeeooooo$",
      "#$$#$$m$$#$$#$$#"
    ],
    [
      "#######fk###mmN#",
      "#,    7777,   ,#",
      "#     777& VV  #",
      "m     777&<55> #",
      "#     7777 ^^  m",
      "# 333333      LN",
      "#ss s > r  , O #",
      "#2222 22       #",
      "#   r2         #",
      "#sO5 22l2      m",
      "N  ^  222    r #",
      "m    2    ^ ^ ,#",
      "#C  &     33333#",
      "#    2   2  &  #",
      "#Ms  2   2sFsF&#",
      "#Um###m  #######"
    ],
    [
      "#aa#aa#iE#aaHq:#",
      "a              a",
      "a              a",
      "H  %           #",
      "a              q",
      "a 55'555       :",
      "#         %    #",
      "a2222 22       a",
      "a    2         a",
      "#    T2l2T   % H",
      ":     222      a",
      "q    2         a",
      "#         55555#",
      "a    2%  2     a",
      "a    2   2 5 5 a",
      "#qq#aaH  #aa#aa#"
    ],
    [
      "#aa#aa#aa#aamaa#",
      "a              a",
      "a              a",
      "m      n       #",
      "a              a",
      "aH          \\  a",
      "#              #",
      "a2222222       a",
      "a    2     n  Ha",
      "#    22l2      m",
      "H    2222      a",
      "H   \\          a",
      "#              #",
      "a        2     a",
      "a        2     a",
      "#::#aam::#aa#aa#"
    ],
    [
      "####::####::m###",
      "#              #",
      "#     mmmm     #",
      "m n   m{    n  #",
      "#     m        #",
      "#              #",
      "#mmmmmmmmmmmmmm#",
      "#2222222       #",
      "#    2     {   #",
      "#    22l2      m",
      "#    2222      #",
      "#              #",
      "# j         n  #",
      "#        2     #",
      "#        2     #",
      "####mmm#########"
    ],
    [
      "############m###",
      "################",
      "######mmmm######",
      "m###############",
      "################",
      "################",
      "#mmmmmmmmmmmmmm#",
      "################",
      "################",
      "#######l#######m",
      "################",
      "################",
      "################",
      "################",
      "################",
      "######m#########"
    ]
  ]
}
