{
  "xsize": 16,
  "zsize": 16,
  "slices": [
    [
      "##   ######   ##",
      "#eeeeeeeeeeeeee#",
      " #333333333333# ",
      " #333333333333# ",
      " #333333333333# ",
      "#eeeeeeeeeeeeee#",
      "#eeeeeeeeeeeeee#",
      "#eeeeeeeeeeeeee#",
      "#eeeeeeeeeeeeee#",
      "#eeeeeeleeeeeee#",
      "#eeeeeeeeeeeeee#",
      " #333333333333# ",
      " #333333333333# ",
      " #333333333333# ",
      "#eeeeeeeeeeeeee#",
      "##   ######   ##"
    ],
    [
      "##:m:######:m:##",
      "##:::#q  q#:::##",
      "q:qmq  &  qmq :m",
      "m:q0q'   'q0q :m",
      "q:qmq   C qmq :m",
      "##2222  222222##",
      "#s   1    r  C #",
      "# 55O      &   #",
      "#             s#",
      "#  r  2l2   r  #",
      "##2  222222222##",
      "m:   r   r   &:q",
      "m:q:q q:q q:qP:m",
      "m:www www www :q",
      "##:::#    #:::##",
      "## m ###### m ##"
    ],
    [
      "##:m::####::m:##",
      "##:::#'  I#:::##",
      "::qmq     qmq :q",
      "0:q:q     q:q ::",
      "::qmq     qmq :q",
      ":#?222  22222?#:",
      "#  %        %  #",
      "#              #",
      "#%             #",
      "#     2l2%     #",
      ":#?  22222222?#:",
      "q:            ::",
      "::qmq qmq qmq :J",
      "q:w w w w w w ::",
      "##:::#    #:::##",
      "## m :####: m ##"
    ],
    [
      "##:m::####::m:##",
      "##:::#    #:::##",
      "q:6H6     6H6 : ",
      "m:6J6     6J6 :m",
      "q:666     666 : ",
      ":#?2222222222?#:",
      "# H           N#",
      "#              #",
      "#            H #",
      "#N  j 2l2  j   #",
      ":#?2222222222?#:",
      " :            :q",
      "m:6H6 6H6 6H6 :m",
      " :w w w w w w :q",
      "##:::#    #:::##",
      "##qmq:####:qmq##"
    ],
    [
      "##:m:######:m:##",
      "##:::#    #:::##",
      " :mmm     mmm : ",
      " :            :m",
      " :mmm  n  mmm : ",
      "##222222222222##",
      "#mmmmmmmmmmmmmm#",
      "# q  q    q  q #",
      "#mmmmmmmmmmmmmm#",
      "#   { 2l2  {   #",
      "##222222222222##",
      " :     n      : ",
      "m:            : ",
      " :www www www : ",
      "##:::#    #:::##",
      "## m ###### m ##"
    ],
    [
      "##   ######   ##",
      "################",
      " ############## ",
      " ############## ",
      " ############## ",
      "################",
      "#mmmmmmmmmmmmmm#",
      "################",
      "#mmmmmmmmmmmmmm#",
      "#######l########",
      "################",
      " ############## ",
      " ############## ",
      " ############## ",
      "################",
      "##   ######   ##"
    ]
  ]
}
