{
  "xsize": 16,
  "zsize": 16,
  "slices": [
    [
      "################",
      "################",
      "################",
      "################",
      "###0########0###",
      "################",
      "################",
      "################",
      "########l#######",
      "################",
      "################",
      "###0########0###",
      "################",
      "################",
      "################",
      "################"
    ],
    [
      "##000##oo##000##",
      "#qEEq  cc  qEEq#",
      "0q  q  cc  q  q0",
      "0qqqq  gg  qqqq0",
      "0uu          uu0",
      "#R  ::::::::  R#",
      "#   :&    &:   #",
      "occ :  0 0 :  sq",
      "occ :  0l0 : C q",
      "#gg :  000 :  s#",
      "#   ::::::::   #",
      "0uu     &    uu0",
      "0qEEq  cc  qEEq0",
      "0q  q  cc  q  q0",
      "#qqqq  gg  qqqq#",
      "##000##qq##000##"
    ],
    [
      "##oEo##EE##oqo##",
      "#qEEq  qq  qEEq#",
      "qq  q  qq  q  qq",
      "qqqqq      qqqq,",
      "a              q",
      "#   ::::::::   #",
      "#   :      :   #",
      "'   :  0 0 :   q",
      "'   :  0l0 :   q",
      "#   :  000 :   #",
      "#   ::::::::   #",
      "q              q",
      "'qEEq  qq  qEEqq",
      "qq  q  qq  q  qa",
      "#qqqq      qqqq#",
      "##oqo##qq##oHo##"
    ],
    [
      "##a?a##??##E?E##",
      "#QQQQ      QQQQ#",
      "'Q??Q  {   Q??Qa",
      "[oooo      oooo]",
      "a  {        {  a",
      "#              #",
      "#   %      %   #",
      "[      0 0     o",
      "[      0l0     o",
      "#      000     #",
      "#   %      %   #",
      "a  {        {  ,",
      "[oooo      oooo]",
      "aQ??Q  {   Q??Qa",
      "#QQQQ      QQQQ#",
      "##H;H##oo##a;a##"
    ],
    [
      "##000##qq##000##",
      "#qqqq  oo  qqqq#",
      "0qqqqqqqqqqqqqq0",
      "0qqqq  oo  qqqq0",
      "0  n        n  0",
      "#  E        E  #",
      "#              #",
      "q  n   0 0   n ,",
      "qqqqqqq0l0qqqqq,",
      "#  n   000   n #",
      "#              #",
      "0  E        E  0",
      "0qqqq  oo  qqqq0",
      "0qqqqqqqqqqqqqq0",
      "#qqqq  oo  qqqq#",
      "##000##HH##000##"
    ],
    [
      "################",
      "################",
      "################",
      "################",
      "################",
      "################",
      "################",
      "################",
      "########l#######",
      "################",
      "################",
      "################",
      "################",
      "################",
      "################",
      "################"
    ]
  ]
}
