{
  "xsize": 16,
  "zsize": 16,
  "slices": [
    [
      "##   ######   ##",
      "#eeeeeeeeeeeeee#",
      " #eeeeeeeeeeee# ",
      " #eooooeeeeeee# ",
      " #eooooeeeeeee# ",
      "#eeooooeeeeeeee#",
      "#eeooooeeeeeeee#",
      "#eeeeeeeeeeeeee#",
      "#eeeeeeeeeeeeee#",
      "#eeeeeeleeeeeee#",
      "#eeeeeeeeeoooee#",
      " #oeeeeeeeoooe# ",
      " #eeeeeeoeoooe# ",
      " #eeeeeeeeeeee# ",
      "#eeeeeeeeeeeeee#",
      "##   ######   ##"
    ],
    [
      "##   ######qmq##",
      "##aaa#    #aaa##",
      " ar8r O   s  ,a ",
      "r 1      r  8 a ",
      " a     r     ra ",
      "##22 2  22   2##",
      "#    8  55 r  s#",
      "#8       >    r#",
      "# r   r        #",
      "#     2l2  2 r #",
      "##2 222222 222##",
      " a   r     2C a ",
      " a&      r   & r",
      " a*r    8   r a ",
      "##aaa#    #aaa##",
      "## m ######q:q##"
    ],
    [
      "##   :####::J:##",
      "##aaa#    #aaa##",
      " a       \\    a ",
      "       %      % ",
      " %         n  a ",
      ":#22 2  22   2#:",
      "#           %  #",
      "#              #",
      "#         %    #",
      "#   \\ 2l2  2   #",
      ":#% 222222 222#:",
      " a         2  a ",
      " a  %\\          ",
      " a            a ",
      "##aaa#    #aaa##",
      "## m :####:q:q##"
    ],
    [
      "##   :####:qmq##",
      "##aaa#    #aaa##",
      " a\\           a ",
      "q   \\         a ",
      " a   q   \\ {  a ",
      ":#2   2      2#:",
      "#Nj   \\        #",
      "#              #",
      "#              #",
      "#   q 2l2m    N#",
      ":# 2  222   2 #:",
      " a           \\a ",
      " a         \\   q",
      " a            a ",
      "##aaa#    #aaa##",
      "##qmq:####:q:q##"
    ],
    [
      "##   ######   ##",
      "##aaa#    #aaa##",
      " a            a ",
      "m    mmq      a ",
      " a   {     {  a ",
      "##            ##",
      "# {            #",
      "#            n #",
      "#              #",
      "# mm{ 2l2{m  m #",
      "##    222     ##",
      " a            a ",
      " a    j        m",
      " a            a ",
      "##aaa#    #aaa##",
      "## m ######   ##"
    ],
    [
      "##   ######   ##",
      "################",
      " ############## ",
      " ############## ",
      " ###ooo######## ",
      "####ooo#########",
      "################",
      "################",
      "################",
      "##mm##ml#mm##m##",
      "################",
      " ############## ",
      " ############## ",
      " ############## ",
      "################",
      "##   ######   ##"
    ]
  ]
}
