{
  "xsize": 16,
  "zsize": 16,
  "slices": [
    [
      "#$$#$$#$$#$$m$$#",
      "$eeeeeeeeeeeeee$",
      "$eeeeeeeeeeeeee$",
      "meeerrrrreeeeee#",
      "$eeerrrrreeeeee$",
      "$eeerrrrreeeeee$",
      "#eeerrrrreeeeee#",
      "$eeerrrrreeeeee$",
      "$eeeeeeeeeeeeee$",
      "#eeeeeeleeeeeeem",
      "$eeeeeeeeerrrre$",
      "$eeeeeeeeerrrre$",
      "#eeeeeeeeerrrre#",
      "$eeeeeeeeerrrre$",
      "$eeeeeeeeeeeeee$",
      "#$$#$$m$$#$$#$$#"
    ],
    [
      "#Um#########m  #",
      "#,   2         #",
      "# r  2 r s 8  &#",
      "m  8        r  #",
      "  1  2         #",
      "          r  ] #",
      "#22 22  2 22 [2#",
      "m      55     r#",
      "Nr M   ^8   r  #",
      "#     2l2      m",
      "#2 222222   22 #",
      "#          2 4  ",
      "#  r        C 8#",
      "#&8   O  r 2   #",
      "#   r        r #",
      "#### #mNm#######"
    ],
    [
      "#qq#aa#aa#aaH  #",
      "a    2         a",
      "a   %2         a",
      "H           n  #",
      "     2  %      a",
      "   \\           a",
      "#22 22  2 22% 2#",
      "q              a",
      ":              a",
      "#     2l2    % H",
      "a2 222222   22 a",
      "a %        2    ",
      "#              #",
      "a          2   a",
      "a    %         a",
      "#aa# aH:q#aa#aa#"
    ],
    [
      "#::#aa#aa#aam  #",
      "a              a",
      "a    2         a",
      "m     \\     {  #",
      "              \\a",
      "   q     m     a",
      "#2    2   2   N#",
      "a\\             a",
      "a              a",
      "#Nj   2l2      m",
      "a     222      a",
      "a    q    \\     ",
      "#          2   #",
      "a              a",
      "a  \\           a",
      "#aa# amHH#aa#aa#"
    ],
    [
      "#######::###m  #",
      "#              #",
      "#     j        #",
      "m           {  #",
      "               m",
      " mm{ mm m{  mm m",
      "#              #",
      "#              m",
      "#             nm",
      "# {   2l2      m",
      "#     222      #",
      "#    {          ",
      "#    mmq       #",
      "#              #",
      "#              #",
      "#### #m#########"
    ],
    [
      "############m###",
      "################",
      "################",
      "m###############",
      "################",
      "#mm##mm#mm##mm##",
      "################",
      "################",
      "################",
      "#######l#######m",
      "################",
      "################",
      "################",
      "################",
      "################",
      "######m#########"
    ]
  ]
}
