{
  "xsize": 16,
  "zsize": 16,
  "slices": [
    [
      "##:::######:::##",
      "#qmmmq         #",
      ":q:::qmmmqm U  :",
      ":qmmmqm        :",
      ":qmmmqm      P :",
      "#q:::qmm       #",
      "#qmmmq      r q#",
      "#    ## ##     #",
      "#m   #   # s C #",
      "#m P # l #     #",
      "#m   # # #     #",
      ": q  ##### qqqq:",
      ":q:q      wqqqq:",
      ": q r&  r wqqqq:",
      "#          qqqq#",
      "##:::######:::##"
    ],
    [
      "5555555555555555",
      "5q666q         5",
      "56JJJ6HHHqm    5",
      "5q'66q         5",
      "5q666q         5",
      "56JJJ6         5",
      "5q66'q      \\ |5",
      "5    ## ##     5",
      "5    #   #     5",
      "5H   #   #     5",
      "5    # # #     5",
      "5    ##### qqqq5",
      "55:5      wqWWq5",
      "5   \\     wqWWq5",
      "5          qqqq5",
      "5555555555555555"
    ],
    [
      "                ",
      "                ",
      "   |     q:     ",
      "                ",
      "                ",
      "   |            ",
      "                ",
      "     #:#:#      ",
      "     # n #      ",
      "     #   #      ",
      "     # # #      ",
      "     ##### qqqq ",
      "  :        qWWq ",
      "           qWWq ",
      "           qqqq ",
      "                "
    ],
    [
      "                ",
      "                ",
      "         H      ",
      "                ",
      "                ",
      "                ",
      "                ",
      "     #####      ",
      "     #####      ",
      "     #####      ",
      "     #####      ",
      "     ##### 6666 ",
      "  :        6: 6 ",
      "           6 :6 ",
      "           6666 ",
      "                "
    ],
    [
      "                ",
      "                ",
      "                ",
      "                ",
      "                ",
      "                ",
      "                ",
      "     55555      ",
      "                ",
      "       |        ",
      "                ",
      "     55555      ",
      "  :             ",
      "                ",
      "                ",
      "                "
    ],
    [
      "                ",
      "                ",
      "                ",
      "                ",
      "                ",
      "                ",
      "                ",
      "                ",
      "                ",
      "                ",
      "                ",
      "                ",
      "  |             ",
      "                ",
      "                ",
      "                "
    ]
  ]
}
