{
  "xsize": 16,
  "zsize": 16,
  "slices": [
    [
      "################",
      "################",
      "################",
      "################",
      "################",
      "################",
      "################",
      "##0##########0##",
      "################",
      "#######l########",
      "################",
      "################",
      "#######d########",
      "################",
      "################",
      "################"
    ],
    [
      "##_u_######_u_##",
      "######mmmm######",
      "_#LLLLLLLLLLLL#_",
      "_#s          s#_",
      "_#s  ssss   s #_",
      "##s  ssss   s ##",
      "# s  ssss   s  #",
      "#22222t 222222 #",
      "# C          & #",
      "#&     l     C #",
      "##2   ###   22##",
      "_#M M M  X   s#_",
      "_#N N N      s#_",
      "_#u   u   X  s#_",
      "######mmmm######",
      "##_u_######_u_##"
    ],
    [
      "##oEo######EqE##",
      "##aaa#    #aaa##",
      "QaLLLLLLLLLLLLar",
      "Qas          sar",
      "Qas  ssss   s ar",
      "##s  ssss   s ##",
      "# s  ssss   s  #",
      "#22222z 222222 #",
      "#   %       %  #",
      "#      l       #",
      "##2   ###   22##",
      "ra  %      %  aQ",
      "ra           saQ",
      "ra           saQ",
      "##aaa#    #aaa##",
      "##HqH######oHo##"
    ],
    [
      "##o?o######Q?Q##",
      "##aaa#    #aaa##",
      "'a  \\      \\  ar",
      "'a            a]",
      "'a   \\   \\    ar",
      "##            ##",
      "#              #",
      "#22222  222222 #",
      "#              #",
      "#      l       #",
      "##2   ###   22##",
      "ra   {    {   a,",
      "[a            a,",
      "ra  \\      \\  a,",
      "##aaa#    #aaa##",
      "##Q;Q######o;o##"
    ],
    [
      "##ooo######   ##",
      "##aaa#qqqq#aaa##",
      " a  n      n  ar",
      "[aqqqqqqqqqqqqa ",
      " a  E      E  ar",
      "##  n      n  ##",
      "#              #",
      "#22222qq222222 #",
      "#qqqqqqqqqqqqqq#",
      "#  j   l    j  #",
      "##{   ###   { ##",
      "ra  n      n  a ",
      " aqqqqqqqqqqqqa]",
      "ra  E      E  a ",
      "##aaa#qqqq#aaa##",
      "##   ######ooo##"
    ],
    [
      "##===######===##",
      "################",
      "=##############=",
      "=##############=",
      "=##############=",
      "################",
      "################",
      "################",
      "################",
      "#######l########",
      "################",
      "=##############=",
      "=##############=",
      "=##############=",
      "################",
      "##===######===##"
    ]
  ]
}
