{
  "xsize": 16,
  "zsize": 16,
  "slices": [
    [
      "#$$#$$#$$#$$m$$#",
      "$eeeeeeee333333$",
      "$eeeeeeee333333$",
      "meeeeeeee333333#",
      "$eeeeeeee333333$",
      "$eeeeeeee333333$",
      "#eeeeeeeeeeeeee#",
      "$eeeeeeeeeeeeee$",
      "$eeeeeeeeeeeeee$",
      "#eeeeeeleeeeeeem",
      "$eeeeeeeeeeeeee$",
      "$eeeeeeeeeeeeee$",
      "#eeeeeeeeeeeeee#",
      "$eeeeeeeeeeeeee$",
      "$eeeeeeeeeeeeee$",
      "#$$#$$m$$#$$#$$#"
    ],
    [
      "############m###",
      "#ss ss s  qqqq #",
      "#ss ss s wqWWq #",
      "m        wqWWq #",
      "#s&C ss   qqqq #",
      "#s&s sM        #",
      "#      r       #",
      "#   O       4  #",
      "# r       r    #",
      "#  1 r3l3      m",
      "#     333  P r #",
      "#qmq w  r      #",
      "#q0q w    s&ss #",
      "#qJq w  & sC s #",
      "#              #",
      "######m#########"
    ],
    [
      "############H###",
      "#ss ss s  qqqq #",
      "#ss ss s wqWWq #",
      "H   %    wqWWq #",
      "#s s ss   qqqq #",
      "#s s ss     '  #",
      "# %          % #",
      "#        %     #",
      "#              #",
      "#    T3l3      H",
      "#     333      #",
      "#qmq w%        #",
      "#q:q'     s %s #",
      "#qmq w         #",
      "#              #",
      "######H#########"
    ],
    [
      "############m###",
      "#         6666 #",
      "#        w6::6 #",
      "m        w6  6 #",
      "#         6666 #",
      "#          \\   #",
      "#  \\           #",
      "#N             #",
      "#  j          \\#",
      "#     3l3   n  m",
      "#     333      #",
      "#mHm w         #",
      "#             N#",
      "#6H6 w \\       #",
      "#              #",
      "######m#########"
    ],
    [
      "############m###",
      "#              #",
      "#              #",
      "m      n       #",
      "#m m m m m m m #",
      "#              #",
      "#              #",
      "#     qmmq     #",
      "#  {           #",
      "#     3l3   {  m",
      "# j m 333 m m m#",
      "#    w         #",
      "#    w         #",
      "#    w         #",
      "#              #",
      "######m#########"
    ],
    [
      "############m###",
      "################",
      "################",
      "m###############",
      "#m#m#m#m#m#m#m##",
      "################",
      "################",
      "################",
      "################",
      "#######l#######m",
      "##m#m#m#m#m#m#m#",
      "################",
      "################",
      "################",
      "################",
      "######m#########"
    ]
  ]
}
