{
  "xsize": 16,
  "zsize": 16,
  "slices": [
    [
      "##   ######   ##",
      "#eeeeeeeeeeeeee#",
      " #eeeeeeeeeeee# ",
      " #eeeeeeeeeeee# ",
      " #eee333333eee# ",
      "#eeee333333eeee#",
      "#eeeeeeeeeeeeee#",
      "#eeeeeeeeeeeeee#",
      "#eeeeeeeeeeeeee#",
      "#eeeeeeleeeeeee#",
      "#eeeeeeeeeeeeee#",
      " #eeeeeeeeeeee# ",
      " #eeeeeeeeeeee# ",
      " #eeeeeeeeeeee# ",
      "#eeeeeeeeeeeeee#",
      "##   ######   ##"
    ],
    [
      "##   ######   ##",
      "##aaa#    #aaa##",
      " a,   7777   ,a:",
      " a ^^ 7777 ^^ am",
      " a*          *a:",
      "## <333333 >  ##",
      "#sL          Os#",
      "#s            s#",
      "#  C        ,  #",
      "#    T2l2T     #",
      "##2  2222222 2##",
      "qa  q:0:q   O am",
      ":ar qmmmq &s &am",
      "qa rqUmUq sCr am",
      "##aaa#    #aaa##",
      "##qmq######   ##"
    ],
    [
      "##   ######   ##",
      "##aaa#    #aaa##",
      " a          % a:",
      " a%           am",
      " a            a:",
      "##  55'55'    ##",
      "#              #",
      "#            % #",
      "#              #",
      "#     2l2      #",
      "##2  2222222 2##",
      "qa  q:::q     aq",
      ":a %qm mq     a:",
      "qa  q ' q     aq",
      "##aaa#    #aaa##",
      "##:0:######qmq##"
    ],
    [
      "##   :####:   ##",
      "##aaa#    #aaa##",
      " a            a:",
      " a            am",
      " a            a:",
      ":#            #:",
      "#              #",
      "# \\            #",
      "#N     n      N#",
      "#     2l2      #",
      ":#222222222222#:",
      "qa  qmmmq     a ",
      ":a  6HHH6  \\  am",
      "qa  q666q     a ",
      "##aaa#    #aaa##",
      "##qmq:####:q:q##"
    ],
    [
      "##   ######   ##",
      "##aaa#    #aaa##",
      " a            a:",
      " a  n mmmm n  am",
      " a            a:",
      "##            ##",
      "# qmmmmmmmmmmq #",
      "#  n        n  #",
      "#      {       #",
      "#     2l2      #",
      "##222222222222##",
      " a            a ",
      " a   n    j   am",
      " a            a ",
      "##aaa#    #aaa##",
      "##   ######555##"
    ],
    [
      "##   ######   ##",
      "################",
      " ############## ",
      " #####mmmm##### ",
      " ############## ",
      "################",
      "##qmmmmmmmmmmq##",
      "################",
      "################",
      "#######l########",
      "################",
      " ############## ",
      " ############## ",
      " ############## ",
      "################",
      "##   ######   ##"
    ]
  ]
}
