{
  "xsize": 16,
  "zsize": 16,
  "slices": [
    [
      "0000000000000000",
      "0##############0",
      "0##############0",
      "0#ffff####ffff#0",
      "0#ffff####ffff#0",
      "0#ffff####ffff#0",
      "0#ffff####ffff#0",
      "0##############0",
      "0##############0",
      "0##############0",
      "0##############0",
      "0##############0",
      "0##############0",
      "0##    >#######0",
      "0##    >#######0",
      "0000000000000000"
    ],
    [
      "00aaaa#aa#aaaa00",
      "0 3333 33 3333 0",
      "a3   O kk F   3a",
      "a35555 kk 55553a",
      "a35DD5    5DD53a",
      "a35DD5    5DD53a",
      "#35555    55553#",
      "a3    0000    3a",
      "a3    0WW0    3a",
      "#3L.. 0WW0 ..L3#",
      "a3L   0000   s3a",
      "a         C    a",
      "a  333&      1 a",
      "a >            a",
      "0 >            0",
      "00aaaa#aa#aaaa00"
    ],
    [
      "00aaaa#aa#aaaa00",
      "0              0",
      "a              a",
      "a              a",
      "a  Kp      Kp  a",
      "a  pp      pp  a",
      "#              #",
      "a     5        a",
      "a              a",
      "#  --      --  #",
      "a        5     a",
      "a              a",
      "a              a",
      "a  >           a",
      "0  >           0",
      "00aaaa#aa#aaaa00"
    ],
    [
      "00aaaa#aa#aaaa00",
      "0              0",
      "a           %  a",
      "a              a",
      "a              a",
      "a              a",
      "#              #",
      "a              a",
      "a              a",
      "#              #",
      "a              a",
      "a              a",
      "a %            a",
      "a   >          a",
      "0   >          0",
      "00aaaa#aa#aaaa00"
    ],
    [
      "00############00",
      "0              0",
      "#     n  n     #",
      "#              #",
      "#              #",
      "#              #",
      "#            n #",
      "#              #",
      "# n            #",
      "#              #",
      "#              #",
      "#              #",
      "#        n     #",
      "#    >         #",
      "0    >         0",
      "00############00"
    ],
    [
      "8JJJJJJJJJJJJJJ8",
      "I##############U",
      "I##############U",
      "I##############U",
      "I##############U",
      "I###h######h###U",
      "I##############U",
      "I##############U",
      "I###########h##U",
      "I######h#######U",
      "I##############U",
      "I##############U",
      "I##h###########U",
      "I##   >########U",
      "I##   >########U",
      "8PPPPPPPPPPPPPP8"
    ]
  ]
}
