{
  "xsize": 16,
  "zsize": 16,
  "slices": [
    [
      "################",
      "##0##########0##",
      "################",
      "##0##########0##",
      "################",
      "################",
      "################",
      "################",
      "########l#######",
      "################",
      "################",
      "################",
      "################",
      "################",
      "################",
      "################"
    ],
    [
      "##000##qq##000##",
      "#Y 7777777777 Y#",
      "0Y 7777777777 Y0",
      "0Y 77O7777X77 Y0",
      "0X i        i X0",
      "# kkkkkkkkkkkk #",
      "#^^^ ^^^^^^ ^^^#",
      "o^^^ ^^0 0^ ^^^R",
      "o^^^ ^^0l0^ ^^^R",
      "#^^^ ^^000^ ^^^#",
      "#^^^ ^^^^^^ ^^^#",
      "0 kkkkkkkkkkkk 0",
      "0^^^ ^^^^^^ ^^^0",
      "0^^^ ^^^^^^ ^^^0",
      "#X&  kkkkkk  &X#",
      "##000##oo##000##"
    ],
    [
      "##aaa##qq##aaa##",
      "#Y     %      Y#",
      "aY            Yo",
      "aY      \\     Yq",
      "a              o",
      "#              #",
      "#              #",
      "q      0 0     q",
      "q      0l0     q",
      "#      000     #",
      "#   %      %   #",
      "o              a",
      "q              a",
      "o  \\        \\  a",
      "#              #",
      "##oHo##HH##qqa##"
    ],
    [
      "##aaa##oo##aaa##",
      "#Y            Y#",
      "qY            Y,",
      "'              ]",
      "qYY  YYYYYY  YY,",
      "#              #",
      "#   {      {   #",
      "[      0 0     ,",
      "[      0l0     ,",
      "#      000     #",
      "#              #",
      "'   {      {   q",
      "[              ,",
      "'              q",
      "#   {      {   #",
      "##a;a##;;##H;a##"
    ],
    [
      "##000##EE##000##",
      "#oooooooooooooo#",
      "0  E        E  0",
      "0              0",
      "0qqqqqqqqqqqqqq0",
      "#   n      n   #",
      "#      n       #",
      "q  n   0 0   n o",
      "qqqqqqq0l0qqqqqo",
      "#  n   000   n #",
      "#      n       #",
      "0   n      n   0",
      "0qqqqqqqqqqqqqq0",
      "0  E        E  0",
      "#oooooooooooooo#",
      "##000##qq##000##"
    ],
    [
      "################",
      "################",
      "################",
      "################",
      "################",
      "################",
      "################",
      "################",
      "########l#######",
      "################",
      "################",
      "################",
      "################",
      "################",
      "################",
      "################"
    ]
  ]
}
