{
  "xsize": 16,
  "zsize": 16,
  "slices": [
    [
      "##   ######   ##",
      "#eeeeeeeeeeeeee#",
      " #eeeeeeeeeeee# ",
      " #eeeeeeeeeeee# ",
      " #eeeeeeeeeeee# ",
      "#eeeeeeeeeeeeee#",
      "#eeeeeeeeeeeeee#",
      "#eeeeeeeeeeeeee#",
      "#eeeeeeeeeeeeee#",
      "#eeeeeeleeeeeee#",
      "#eeeeeeeeeeeeee#",
      " #eeeeeeeeeeee# ",
      " #eeeeeeeeeeee# ",
      " #eeeeeeeeeeee# ",
      "#eeeeeeeeeeeeee#",
      "##   ######   ##"
    ],
    [
      "##   ######   ##",
      "##aaa#    #aaa##",
      "qa,7^^^^^^777,aq",
      "ma <555555>7O a:",
      "qas7VVVVVV777Laq",
      "##?? 22222?? 2##",
      "# L  ,     &  s#",
      "#55O         55#",
      "#^          C^ #",
      "#     2l2 r    #",
      "##    222     ##",
      " a2?2 2222 2?2aq",
      " a 5^ r,  5^  am",
      "qaF5F5&s*5s&sCaq",
      "##aaa#    #aaa##",
      "##   ######mmm##"
    ],
    [
      "##:::######qmq##",
      "##aaa#    #aaa##",
      ":a       %    aq",
      "Ja           %a:",
      ":a%           aq",
      "##?? 22222?? 2##",
      "#              #",
      "#              #",
      "#              #",
      "#   %T2l2T     #",
      "##    222     ##",
      " a2?2 2222 2?2a:",
      "qa          % a0",
      "ma  5 %       a:",
      "##aaa#    #aaa##",
      "##   ######q:q##"
    ],
    [
      "##mmm:####:q:q##",
      "##aaa#    #aaa##",
      "qa            aq",
      "ma \\          a:",
      "qa            aq",
      ":#??2H2222?H22#:",
      "#              #",
      "#N             #",
      "# n          n #",
      "#     2l2     N#",
      ":#    222     #:",
      "qa2?2H22222H?2aq",
      "ma      \\     am",
      "qa            aq",
      "##aaa#    #aaa##",
      "##   :####: m ##"
    ],
    [
      "##   ######555##",
      "##aaa#    #aaa##",
      " a            a ",
      " a  n      n  a ",
      " a            a ",
      "##mmmmmmmmmmmm##",
      "#      m       #",
      "#      m       #",
      "# {    m     { #",
      "#     2l2      #",
      "##    222     ##",
      " ammmmmmmmmmmma ",
      "5a            a ",
      " a n        j a ",
      "##aaa#    #aaa##",
      "##   ###### m ##"
    ],
    [
      "##   ######   ##",
      "################",
      " ############## ",
      " ############## ",
      " ############## ",
      "##mmmmmmmmmmmm##",
      "################",
      "################",
      "################",
      "#######l########",
      "################",
      " #mmmmmmmmmmmm# ",
      " ############## ",
      " ############## ",
      "################",
      "##   ######   ##"
    ]
  ]
}
