{
  "xsize": 16,
  "zsize": 16,
  "slices": [
    [
      "################",
      "################",
      "####0######0####",
      "################",
      "################",
      "################",
      "################",
      "################",
      "########l#######",
      "################",
      "################",
      "################",
      "################",
      "####0######0####",
      "################",
      "################"
    ],
    [
      "##000##qq##000##",
      "#F6F6F6F 3&sss #",
      "06      63s   O0",
      "06  //  63s  & 0",
      "0F6F6F6F 3ssss 0",
      "#33333t333  kkk#",
      "# kkkkkkkkkkkk #",
      "qX5555 0 0 55 Xo",
      "q >  < 0l0 > < o",
      "#X5555 000 55 X#",
      "# kkkkkkkkkkkk #",
      "0X ^^  ^^  ^^ X0",
      "0X 55  55  55 X0",
      "0X VV  VV  VV X0",
      "#Xkkkkkkkkkkk X#",
      "##000##RR##000##"
    ],
    [
      "##oqo##oo##aaa##",
      "#s s s s 3s  s #",
      "a       %3     a",
      "q       83s    q",
      "as s s s 3ssss q",
      "#33333z333     #",
      "#              #",
      "' Y    0 0    Yq",
      "'      0l0     q",
      "# Y    000    Y#",
      "#              #",
      "a   %      %   a",
      "q              q",
      "q  \\        \\  a",
      "#              #",
      "##qqa##qq##oHo##"
    ],
    [
      "##E?E##EE##aaa##",
      "#  {   { 2  {  #",
      "a        2     a",
      "'  \\     2     ]",
      "a        2   \\ ,",
      "#333333333     #",
      "#              #",
      "q      0 0     ]",
      "q   {  0l0  {  ]",
      "#      000     #",
      "#              #",
      "a   {      {   a",
      "[              ,",
      "'   {      {   a",
      "#  \\        \\  #",
      "##H;a##HH##a;a##"
    ],
    [
      "##000##qq##000##",
      "#qqqqqqq q oooo#",
      "0  n    q q    0",
      "0  E    q q  n 0",
      "0qqqqqqq q oooo0",
      "#       q      #",
      "#  n        n  #",
      "o      0 0     q",
      "oqqqqqq0l0qqqqqq",
      "#      000     #",
      "#  n        n  #",
      "0  E        E  0",
      "0oooooooooooooo0",
      "0  n        n  0",
      "#              #",
      "##000##oo##000##"
    ],
    [
      "################",
      "################",
      "################",
      "################",
      "################",
      "################",
      "################",
      "################",
      "########l#######",
      "################",
      "################",
      "################",
      "################",
      "################",
      "################",
      "################"
    ]
  ]
}
