{
  "xsize": 16,
  "zsize": 16,
  "slices": [
    [
      "################",
      "################",
      "################",
      "################",
      "#####d##########",
      "################",
      "################",
      "###########d####",
      "################",
      "#######l########",
      "################",
      "####d###########",
      "################",
      "################",
      "################",
      "################"
    ],
    [
      "##___######___##",
      "######mmmm######",
      "_#O5555 O 5555#_",
      "u#^^^^^  ^^^^^#_",
      "_#kkkkk  kkkkk#_",
      "##2222`  `2222##",
      "#  mmmmmmmmmm  #",
      "#s  555  555  s#",
      "#s  ^^^  ^^^  s#",
      "#&     l      C#",
      "##22  ###  222##",
      "_#O5555  55555#_",
      "_#^^^^^  ^^^^^#u",
      "_#kkkkkkkkkkkk#_",
      "######mmmm######",
      "##___######___##"
    ],
    [
      "##o?o######rrr##",
      "##aaa#    #aaa##",
      "qas   s  s   saQ",
      "qa            aQ",
      "qa            aQ",
      "##2222`  `2222##",
      "#              #",
      "#   %      %   #",
      "#              #",
      "#      l       #",
      "##22  ###  222##",
      "Qas   s  s    aq",
      "Qa  %       % aq",
      "Qa            aq",
      "##aaa#    #aaa##",
      "##rrr######o;o##"
    ],
    [
      "##oEo######r?r##",
      "##aaa#    #aaa##",
      "qa  \\      \\  a,",
      "[a            a,",
      "qa            a,",
      "##``` `  ` ```##",
      "#              #",
      "#  %        %  #",
      "#              #",
      "#      l       #",
      "##``  ###  ```##",
      "'a            aq",
      "'a   \\     \\  a]",
      "'a            aq",
      "##aaa#    #aaa##",
      "##r;r######oHo##"
    ],
    [
      "## { ######r r##",
      "##aaa#qqqq#aaa##",
      "'a  n      n  a ",
      "'aqqqqqqqqqqqqa]",
      "'a  E      E  a ",
      "##            ##",
      "# n          n #",
      "#              #",
      "#qqqqqqqqqqqqqq#",
      "#  n   l    n  #",
      "## {  ###   { ##",
      " a  n      n  a,",
      "[aqqqqqqqqqqqqa,",
      " a  E      E  a,",
      "##aaa#qqqq#aaa##",
      "##r r###### { ##"
    ],
    [
      "##===######===##",
      "################",
      "=##############=",
      "=##############=",
      "=##############=",
      "################",
      "################",
      "################",
      "################",
      "#######l########",
      "################",
      "=##############=",
      "=##############=",
      "=##############=",
      "################",
      "##===######===##"
    ]
  ]
}
