{
  "xsize": 16,
  "zsize": 16,
  "slices": [
    [
      "0000000000000000",
      "0 oooooo       0",
      "0 oWWWWo   qqq 0",
      "0 oWWWWo   q&q 0",
      "0 oooooo   qqq 0",
      "0  }           0",
      "0     00 00    0",
      "0     0   0    0",
      "0     0 l 0    0",
      "0     00000    0",
      "0  u    0   u  0",
      "0 \"\"\"          0",
      "0    qqqqqq    0",
      "0    qEEEEq    0",
      "0    qqqqqq    0",
      "0000000000000000"
    ],
    [
      "0::::::::::::::0",
      ": oooooo       :",
      ": o    o   qEq :",
      ": o    o   q?q :",
      ": oooooo   qqq :",
      ":              :",
      ":     00 00    :",
      ":     0   0    :",
      ":     0 l 0    :",
      ":     00000    :",
      ":  {    :   {  :",
      ":              :",
      ":    qqqqqq    :",
      ":    q((((q    :",
      ":    qqqqqq    :",
      "0::::::::::::::0"
    ],
    [
      "0              0",
      "  oooooo        ",
      "  o((((o   qqq  ",
      "  o((((o   q(q  ",
      "  oooooo   qqq  ",
      "                ",
      "     UPPPPPI    ",
      "     U00000I    ",
      "     U00000I    ",
      "     UJJJJJI    ",
      "        :       ",
      "                ",
      "                ",
      "                ",
      "                ",
      "0              0"
    ],
    [
      "                ",
      "                ",
      "  |        |    ",
      "                ",
      "                ",
      "                ",
      "                ",
      "                ",
      "                ",
      "                ",
      "        |       ",
      "                ",
      "                ",
      "                ",
      "                ",
      "                "
    ],
    [
      "                ",
      "                ",
      "                ",
      "                ",
      "                ",
      "                ",
      "                ",
      "                ",
      "                ",
      "                ",
      "        |       ",
      "                ",
      "                ",
      "                ",
      "                ",
      "                "
    ],
    [
      "                ",
      "                ",
      "                ",
      "                ",
      "                ",
      "                ",
      "                ",
      "                ",
      "                ",
      "                ",
      "                ",
      "                ",
      "                ",
      "                ",
      "                ",
      "                "
    ]
  ]
}
