{
  "xsize": 16,
  "zsize": 16,
  "slices": [
    [
      "################",
      "################",
      "################",
      "############d###",
      "################",
      "################",
      "################",
      "################",
      "####d###########",
      "#######l########",
      "################",
      "################",
      "#########d######",
      "################",
      "################",
      "################"
    ],
    [
      "##_u_######_u_##",
      "######AAAA######",
      "_#M M 2  2s  s#_",
      "_#N N 2  2   X#u",
      "_#    2  2X   #_",
      "##22t22  22t22##",
      "# k          k #",
      "# F.  X  X  .F #",
      "# u          u #",
      "#&  i  l   i  C#",
      "##2   ###   22##",
      "_#s  X    X  s#_",
      "u#M M      M M#_",
      "_#N N      N N#_",
      "######AAAA######",
      "##_u_######_u_##"
    ],
    [
      "##EqE######qqq##",
      "##aaa#    #aaa##",
      "oa  ` 2  2s  sao",
      "[a    2  2    a,",
      "oa    2  2    ao",
      "##22z22  22z22##",
      "#              #",
      "# s        s   #",
      "#   %      %   #",
      "#      l       #",
      "##2   ###   22##",
      "oa2  2s  s2  2ao",
      "'a            a]",
      "oa  %      %  ao",
      "##aaa#    #aaa##",
      "##qqq######HqH##"
    ],
    [
      "##Q?Q######q?q##",
      "##aaa#    #aaa##",
      "oa  \\ 2  2   \\ao",
      "'a    2  2    a]",
      "oa    2  2    ao",
      "##22 22  22 22##",
      "#              #",
      "#              #",
      "#  \\        \\  #",
      "#      l       #",
      "##2   ###   22##",
      "oa2  2   2   2ao",
      "[a            a,",
      "oa            ao",
      "##aaa#    #aaa##",
      "##q;q######Q;Q##"
    ],
    [
      "##   ######EEE##",
      "##aaa#  n #aaa##",
      " a  n 2  2 n  ao",
      "{a    2  2    ao",
      " a    2  2    ao",
      "##22222qq22222##",
      "#    qqqqqq    #",
      "# n  q    q  n #",
      "#    qqqqqq    #",
      "#      l       #",
      "##2   ###   22##",
      "oa  n      n  a ",
      "oa            a{",
      "oa  E      E  a ",
      "##aaa# n  #aaa##",
      "##HHH######   ##"
    ],
    [
      "##===######===##",
      "################",
      "=##############=",
      "=##############=",
      "=##############=",
      "################",
      "################",
      "################",
      "################",
      "#######l########",
      "################",
      "=##############=",
      "=##############=",
      "=##############=",
      "################",
      "##===######===##"
    ]
  ]
}
