{
  "xsize": 16,
  "zsize": 16,
  "slices": [
    [
      "################",
      "################",
      "################",
      "###0##########0#",
      "################",
      "################",
      "##0##########0##",
      "################",
      "########l#######",
      "####0#####0#####",
      "################",
      "################",
      "##0##########0##",
      "################",
      "################",
      "################"
    ],
    [
      "##000##qq##000##",
      "#Xsss O  O sssX#",
      "0 555555555555 0",
      "0 > kkkkkkkk < 0",
      "0Xk  ^^^^^^  kX0",
      "#Xkkkkkkkkkkk X#",
      "# kkkkkkkkkkkk #",
      "qs655  0 0 O&ssq",
      "qs/  > 0l0  C sq",
      "#s655  000  O s#",
      "# kkkkkkkkkkkk #",
      "0X> kkkkkkkk <X0",
      "0Xk 5 kkkk 5 kX0",
      "0X> kkkkkkkk <X0",
      "#Xs  kkkkkkk sX#",
      "##000##  ##000##"
    ],
    [
      "##qqa##EE##aqq##",
      "# s        s   #",
      "o  `````````   a",
      "'              a",
      "o   %      %   a",
      "#              #",
      "#              #",
      "o Y    0 0    Y,",
      "o  s   0l0   s ,",
      "# Y    000    Y#",
      "#              #",
      "a   %      %   o",
      "a              ,",
      "a    \\    \\    o",
      "#  s        s  #",
      "##aqa##  ##aqa##"
    ],
    [
      "##E?a##qq##a?E##",
      "#  \\        \\  #",
      "a              a",
      "[   {      {   a",
      "a              a",
      "#              #",
      "#              #",
      "'      0 0     q",
      "'      0l0     q",
      "#      000     #",
      "#              #",
      "a   {      {   a",
      "a              ]",
      "a  \\        \\  a",
      "#              #",
      "##aHa##;;##aHa##"
    ],
    [
      "##000##oo##000##",
      "#  n        n  #",
      "0qqqqqqqqqqqqqq0",
      "0  E        E  0",
      "0   n      n   0",
      "#              #",
      "#qqqqqq  qqqqqq#",
      "q  n   0 0   n o",
      "q      0l0     o",
      "#  n   000   n #",
      "#qqqqqq  qqqqqq#",
      "0   n      n   0",
      "0  E        E  0",
      "0qqqqqqqqqqqqqq0",
      "#  n        n  #",
      "##000##qq##000##"
    ],
    [
      "################",
      "################",
      "################",
      "################",
      "################",
      "################",
      "################",
      "################",
      "########l#######",
      "################",
      "################",
      "################",
      "################",
      "################",
      "################",
      "################"
    ]
  ]
}
