{
  "xsize": 16,
  "zsize": 16,
  "slices": [
    [
      "################",
      "#333333ee33333e#",
      "#333333ee33333e#",
      "#333333ee33333e#",
      "#333333eeeeeeee#",
      "#eeeeeeeeeeeeee#",
      "#eeeeeeeeeeeeee#",
      "#eeeeeeeeeeeeee#",
      "#eeeeeeeeeeeeee#",
      "#eeeeeeleeeeeee#",
      "#eeeeeeeeeeeeee#",
      "#eeeeeeeeeeeeee#",
      "#e3333eeeeeeeee#",
      "#eeeeeeeeeeeeee#",
      "#eeeeeeeeeeeeee#",
      "################"
    ],
    [
      "################",
      "#qmmmmq  FPFPF #",
      "#q:00:q  wwwww #",
      "#qmmmmq  q:q:q #",
      "#qUqqUq        #",
      "#              #",
      "#        P   r #",
      "#  r  O        #",
      "#   &       1  #",
      "# r   3l3 r    #",
      "#     333      #",
      "#ss&s   r  &ss #",
      "#sC sr     s M #",
      "#&ss        s& #",
      "#              #",
      "################"
    ],
    [
      "################",
      "#qmmmmq  w w w #",
      "#q::::q        #",
      "#qmmmmq  qmqmq #",
      "#q '' q        #",
      "#              #",
      "# %            #",
      "#          %   #",
      "#    %         #",
      "#    T3l3T     #",
      "#  %  333    % #",
      "#ss s          #",
      "#s  s %    s   #",
      "#           %  #",
      "#              #",
      "################"
    ],
    [
      "################",
      "#qHHHHq  w w w #",
      "#qJ  Jq        #",
      "#q6666q  mHmHm #",
      "#q    q        #",
      "#              #",
      "#N  n      n\\  #",
      "#   \\          #",
      "#      n       #",
      "#     3l3     N#",
      "#     333      #",
      "#              #",
      "# \\      \\     #",
      "#              #",
      "#              #",
      "################"
    ],
    [
      "################",
      "#mmmmmm  wwwww #",
      "#     j   m m  #",
      "#mmmmmm  mmmmm #",
      "#              #",
      "# qmmmmmmmmmmq #",
      "#   {      {   #",
      "#           j  #",
      "# m m m m m m  #",
      "#     3l3      #",
      "#     333      #",
      "#              #",
      "#  j         n #",
      "#              #",
      "#              #",
      "################"
    ],
    [
      "################",
      "################",
      "############q###",
      "############q###",
      "################",
      "##qmmmmmmmmmmq##",
      "####q######q####",
      "################",
      "################",
      "#######l########",
      "################",
      "################",
      "################",
      "################",
      "################",
      "################"
    ]
  ]
}
