{
  "xsize": 16,
  "zsize": 16,
  "slices": [
    [
      "#$$#$$#$$#$$m$$#",
      "$333333eeeeeeee$",
      "$333333eeeeeeee$",
      "m333333eeeeeeee#",
      "$333333eeeeeeee$",
      "$eeeeeeeeeeeeee$",
      "#eeeeeeeeeeeeee#",
      "$eeeeeeeeeeeeee$",
      "$eeeeeeeeeeeeee$",
      "#eeeeeeleeeeeeem",
      "$eeeeeeeeeeeeee$",
      "$eeeeeeee333333$",
      "#eeeeeeee333333#",
      "$eeeeeeee333333$",
      "$eeeeeeee333333$",
      "#$$#$$m$$#$$#$$#"
    ],
    [
      "############m###",
      "#qmmq FPFP FP  #",
      "#q00q wwww   & #",
      "mqmmq          #",
      "#qUUq     wq:q #",
      "#         wqmq #",
      "#       r&w    #",
      "#  r      wq:q #",
      "#   1 O   wqmq #",
      "# r   3l3r     m",
      "#     333   P  #",
      "#ss&s        r #",
      "#sC s s&s &ss  #",
      "#&ss rsMs  s&  #",
      "#              #",
      "######m#########"
    ],
    [
      "############H###",
      "#qmmq w w      #",
      "#q::q          #",
      "Hqmmq        % #",
      "# ''      wqmq #",
      "#          q%q #",
      "# %       w    #",
      "#          qmq #",
      "#         wq q #",
      "#    T3l3T     H",
      "#     333      #",
      "#ss s%         #",
      "#s  s s%s      #",
      "#        %     #",
      "#              #",
      "######H#########"
    ],
    [
      "############m###",
      "#qHHq w w      #",
      "#qJJq          #",
      "mq66q   \\      #",
      "#         w6H6 #",
      "#              #",
      "#   \\     w    #",
      "#   n      6H6 #",
      "#N        w    #",
      "#     3l3  \\   m",
      "#     333     N#",
      "#          j   #",
      "# \\            #",
      "#              #",
      "#              #",
      "######m#########"
    ],
    [
      "############m###",
      "#mmmm wwww     #",
      "#      j       #",
      "mmmmm          #",
      "#         w    #",
      "#         w    #",
      "#mmmmmmmmmmmmmm#",
      "#   {     w    #",
      "#         w  n #",
      "#     3l3      m",
      "#     333      #",
      "#          {   #",
      "#mmmmmmmmmmmmmm#",
      "# n            #",
      "#              #",
      "######m#########"
    ],
    [
      "############m###",
      "################",
      "################",
      "m###############",
      "################",
      "################",
      "#mmmmmmmmmmmmmm#",
      "################",
      "################",
      "#######l#######m",
      "################",
      "################",
      "#mmmmmmmmmmmmmm#",
      "################",
      "################",
      "######m#########"
    ]
  ]
}
