{
  "xsize": 16,
  "zsize": 16,
  "slices": [
    [
      "############m###",
      "#   mmmmmmmmm  #",
      "#qmmqw     r   #",
      "mqI:qw         #",
      "#mmmmw      &  #",
      "#qmmq         s#",
      "#qI:q       U  #",
      "#    ## ##   r #",
      "# P  #   #     #",
      "#q  &# l #     m",
      "#  C # # #qwwwq#",
      "#    #####w   w#",
      "#22   m   w   w#",
      "#22r  m   w   w#",
      "#     mm  qwwwq#",
      "######m#########"
    ],
    [
      "____________m___",
      "_    H   H     _",
      "_q'6qw         _",
      "m6JJ6        \\ _",
      "_    w         _",
      "_q66q          _",
      "_6JJ6          _",
      "_    ## ##     _",
      "_    #   #     _",
      "_|   #   #     m",
      "_    # # #qqqqq_",
      "_   \\#####qqqqq_",
      "_22      wqqqqq_",
      "_22      wqqqqq_",
      "_     H   qqqqq_",
      "______m_________"
    ],
    [
      "                ",
      "                ",
      "                ",
      "  |             ",
      "                ",
      "                ",
      "  |             ",
      "     #?#?#      ",
      "     # n #      ",
      "     #   #      ",
      "     # # #qqqqq ",
      "     #####qWWWq ",
      " 22      wqWWWq ",
      " 22      wqWWWq ",
      "          qqqqq ",
      "                "
    ],
    [
      "                ",
      "                ",
      "                ",
      "                ",
      "                ",
      "                ",
      "                ",
      "     #####      ",
      "     #####      ",
      "     #####      ",
      "     #####qqqqq ",
      "     #####qWWWq ",
      " 22       qWWWq ",
      " 22       qWWWq ",
      "          qqqqq ",
      "                "
    ],
    [
      "                ",
      "                ",
      "                ",
      "                ",
      "                ",
      "                ",
      "                ",
      "     _____      ",
      "                ",
      "       |        ",
      "          _____ ",
      "     ______   _ ",
      " 22       _ : _ ",
      " 22       _   _ ",
      "          _____ ",
      "                "
    ],
    [
      "                ",
      "                ",
      "                ",
      "                ",
      "                ",
      "                ",
      "                ",
      "                ",
      "                ",
      "                ",
      "                ",
      "                ",
      " ::             ",
      " ::             ",
      "                ",
      "                "
    ]
  ]
}
