{
  "xsize": 16,
  "zsize": 16,
  "slices": [
    [
      "################",
      "################",
      "###dd######d####",
      "##ddd###########",
      "####d######dd###",
      "################",
      "##########dd####",
      "###dd###########",
      "################",
      "#######l########",
      "################",
      "#####dd#####dd##",
      "################",
      "###d######d#####",
      "################",
      "################"
    ],
    [
      "##_}_######___##",
      "######vv v######",
      "_#}v  \\   v}  #_",
      "}#  }   \\   } #_",
      "_# v   }}   v #_",
      "##22} }  } }22##",
      "#  }        }  #",
      "# } O  i O  }  #",
      "#   \\  }   \\   #",
      "#}     l     1 #",
      "## }v ### v  }##",
      "_#}   \\  i &  #_",
      "_# v   }   v  #}",
      "_#  }     \\  }#_",
      "######v }v######",
      "##_}_######___##"
    ],
    [
      "##   ######q q##",
      "##aaa#    #aaa##",
      " a \\      \\   ar",
      " a            ar",
      " a  \\     \\   ar",
      "##22  }   } 22##",
      "# \\          \\ #",
      "#     \\        #",
      "#   \\      \\   #",
      "#      l       #",
      "##    ###     ##",
      "qa \\       \\  a ",
      " a            a ",
      "qa   \\    \\   a ",
      "##aaa#    #aaa##",
      "##   ######rrr##"
    ],
    [
      "## { ######q?q##",
      "##aaa#    #aaa##",
      " a  {      {  ar",
      "{a            a]",
      " a    \\   \\   ar",
      "##2}  }  }  }2##",
      "#  \\         \\ #",
      "#              #",
      "#     \\   \\    #",
      "#      l       #",
      "##    ###     ##",
      "qa  {      {  a ",
      "[a            a{",
      "qa  \\      \\  a ",
      "##aaa#    #aaa##",
      "## { ######r;r##"
    ],
    [
      "## { ######qqq##",
      "##aaa#q  q#aaa##",
      " aqq}  \\  }qq ar",
      "{a        }   a ",
      " a {       {  ar",
      "##}  }    }  }##",
      "#  qq}    }qq  #",
      "#     n        #",
      "#  }        }  #",
      "#      l    j  #",
      "##}   ###   } ##",
      "qaq}       }q a ",
      "qa            a{",
      "qa  {      {  a ",
      "##aaa#}  }#aaa##",
      "## { ######r r##"
    ],
    [
      "##===######===##",
      "################",
      "=##############=",
      "=####dd#######d=",
      "=##############=",
      "################",
      "################",
      "######dd########",
      "################",
      "#######l########",
      "################",
      "=##############=",
      "=###d#########d=",
      "=##############=",
      "################",
      "##===######===##"
    ]
  ]
}
