{
  "xsize": 16,
  "zsize": 16,
  "slices": [
    [
      "0000000000000000",
      "0222222222222220",
      "0222222222222220",
      "0222222222222220",
      "0222222222222220",
      "0222222222222220",
      "0222222222222220",
      "0222222222222220",
      "0222222222222220",
      "0222222222222220",
      "0222222222222220",
      "0222222222222220",
      "0222222222222220",
      "0222222222222220",
      "0222222222222220",
      "0000000000000000"
    ],
    [
      "0222222222222220",
      "2F  O2   0     2",
      "2    2 4 0 C C 2",
      "2 qq 2   0  q  2",
      "2}   2   0 & & 2",
      "2        0s   s2",
      "222222   00: :02",
      "2              2",
      "2sss sss     & 2",
      "2   &   C F    2",
      "2sss sss    O  2",
      "2          1   2",
      "2  333}  }     2",
      "2 >            2",
      "2 >            2",
      "0222222222222220"
    ],
    [
      "0222222222222220",
      "2    2   0%    2",
      "2    2   0     2",
      "2 :: 2   0  8  2",
      "2    2   0     2",
      "2        0     2",
      "222222   00: :02",
      "2              2",
      "2s    s%       2",
      "2            % 2",
      "2s    s        2",
      "2  %           2",
      "2              2",
      "2  >           2",
      "2  >           2",
      "0222222222222220"
    ],
    [
      "0222222222222220",
      "2    2   0     2",
      "2    2   0     2",
      "2 {{ 2%  0     2",
      "2    2   0     2",
      "2       %0     2",
      "222222   00:::02",
      "2 %            2",
      "2     \\        2",
      "2              2",
      "2              2",
      "2              2",
      "2             %2",
      "2   >          2",
      "2   >          2",
      "0222222222222220"
    ],
    [
      "0222222222222220",
      "2    2   0     2",
      "2  j 2   0     2",
      "2 {  2   0  j  2",
      "2    2   0     2",
      "2    2   0     2",
      "222222 j 0000002",
      "2              2",
      "2              2",
      "2              2",
      "2              2",
      "2              2",
      "2           j  2",
      "2    >         2",
      "2    >         2",
      "0222222222222220"
    ],
    [
      "8JJJJJJJJJJJJJJ8",
      "I##############U",
      "I##############U",
      "I##############U",
      "I##############U",
      "I##############U",
      "I##############U",
      "I##############U",
      "I##############U",
      "I##############U",
      "I##############U",
      "I##############U",
      "I##############U",
      "I##   >########U",
      "I##   >########U",
      "8PPPPPPPPPPPPPP8"
    ]
  ]
}
