{
  "xsize": 16,
  "zsize": 16,
  "slices": [
    [
      "################",
      "################",
      "################",
      "################",
      "################",
      "################",
      "##0##########0##",
      "################",
      "################",
      "#######l########",
      "##0##########0##",
      "################",
      "################",
      "################",
      "################",
      "################"
    ],
    [
      "##___######_u_##",
      "######mmmm######",
      "_#X          X#_",
      "_# VVVVVVVVVV #_",
      "_# 5555555555 #_",
      "## ^^^^^^^^^^ ##",
      "#2233  33  3322#",
      "# X  7mmmm7  X #",
      "# s   5  5   s #",
      "#&s    l    s C#",
      "##2   ###   22##",
      "_#F.O    X   s#_",
      "_#F.     kkk s#_",
      "_#&    >  <  s#_",
      "######mmmm######",
      "##_u_######___##"
    ],
    [
      "##QQQ######oEo##",
      "##aaa#    #aaa##",
      "ra            ao",
      "ra            a]",
      "ra            ao",
      "##            ##",
      "#2```  ``  ```2#",
      "#  %        %  #",
      "# s          s #",
      "# s    l     s #",
      "##2   ###   22##",
      "oas      %   sar",
      "[as          sar",
      "oa           sar",
      "##aaa#    #aaa##",
      "##oHo######QQQ##"
    ],
    [
      "##EEE######o?o##",
      "##aaa#    #aaa##",
      "ra            ao",
      "[a  \\      \\  a,",
      "ra            ao",
      "##            ##",
      "#2```  ``  ```2#",
      "#              #",
      "#   \\      \\   #",
      "#      l       #",
      "##2   ###   22##",
      "oa            ar",
      "'a   \\    \\   a]",
      "oa            ar",
      "##aaa#    #aaa##",
      "##o;o######HHH##"
    ],
    [
      "## ? ######ooo##",
      "##aaa#qqqq#aaa##",
      "ra  n      n  a ",
      " aqqqqqqqqqqqqa{",
      "ra  E      E  a ",
      "##            ##",
      "#2qqqqqqqqqqqq2#",
      "# n          n #",
      "#              #",
      "#  n   l    n  #",
      "##{   ###   { ##",
      " a  n      n  ar",
      "{aqqqqqqqqqqqqa ",
      " a  E      E  ar",
      "##aaa#qqqq#aaa##",
      "##ooo###### ; ##"
    ],
    [
      "##===######===##",
      "################",
      "=##############=",
      "=##############=",
      "=##############=",
      "################",
      "################",
      "################",
      "################",
      "#######l########",
      "################",
      "=##############=",
      "=##############=",
      "=##############=",
      "################",
      "##===######===##"
    ]
  ]
}
