{
  "xsize": 16,
  "zsize": 16,
  "slices": [
    [
      "0000000000000000",
      "0    }        }0",
      "0 qEEEq  oEEEo 0",
      "0 q   q  o   o 0",
      "0 qHHHq  oHHHo 0",
      "0 uu   0    u  0",
      "0    \"\"\"       0",
      "0    00 00     0",
      "0    0   0 qqqq0",
      "0    0 l 0 qWWq0",
      "0    00000 qWWq0",
      "0          qqqq0",
      "0 rrrr        }0",
      "0 r  r    }    0",
      "0 rrrr         0",
      "0000000000000000"
    ],
    [
      "0::::::::::::::0",
      ":              :",
      ": qqqqq  ooooo :",
      ": q(((q  o(((o :",
      ": qqqqq  ooooo :",
      ":   {  :    {  :",
      ":              :",
      ":    00 00     :",
      ":    0   0 oooo:",
      ":    0 l 0 oWWo:",
      ":    00000 oWWo:",
      ":          oooo:",
      ": rrrr         :",
      ": r((r         :",
      ": rrrr         :",
      "0::::::::::::::0"
    ],
    [
      "0              0",
      "                ",
      "   |       |    ",
      "                ",
      "                ",
      "       :        ",
      "                ",
      "    UPPPPPI     ",
      "    U00000Ioooo ",
      "    U00000IoWWo ",
      "    UJJJJJIoWWo ",
      "           oooo ",
      "                ",
      "               |",
      "                ",
      "0              0"
    ],
    [
      "                ",
      "                ",
      "                ",
      "                ",
      "                ",
      "       |        ",
      "                ",
      "                ",
      "           oooo ",
      "           o\"\"o ",
      "           o\"\"o ",
      "           oooo ",
      "                ",
      "                ",
      "                ",
      "                "
    ],
    [
      "                ",
      "                ",
      "                ",
      "                ",
      "                ",
      "       |        ",
      "                ",
      "                ",
      "                ",
      "           |    ",
      "                ",
      "                ",
      "                ",
      "                ",
      "                ",
      "                "
    ],
    [
      "                ",
      "                ",
      "                ",
      "                ",
      "                ",
      "                ",
      "                ",
      "                ",
      "                ",
      "                ",
      "                ",
      "                ",
      "                ",
      "                ",
      "                ",
      "                "
    ]
  ]
}
