{
  "xsize": 16,
  "zsize": 16,
  "slices": [
    [
      "##:::#####rrrr##",
      "#qqqqq         #",
      ":qqqqqwq     q :",
      ":qqqqqw     r  :",
      ":qqqqqw q      :",
      "#qqqqq     qmmq#",
      "#         mq::q#",
      "#    ## ##mqmmq#",
      "# P  #   #m   U#",
      "#   r# l #mqmmq#",
      "#q   # # #mq::q#",
      ":    #####mqmmq:",
      ": &       m    :",
      ":r C  mmmr s & :",
      "#              #",
      "##:::######:::##"
    ],
    [
      "5555555555    55",
      "5qqqqq          ",
      "5qWWWq:m    :m  ",
      "5qWWWq          ",
      "5qWWWqw:m   \\  5",
      "5qqqqq     q66q5",
      "5         H6JJ65",
      "5    ## ## q66q5",
      "5    #   # '   5",
      "5    #   # q66q5",
      "5|   # # # 6JJ65",
      "5    ##### q66q5",
      "5  \\      H    5",
      "5      H       5",
      "5              5",
      "5555555555555555"
    ],
    [
      "                ",
      " q'qqq          ",
      " qWWWqwm     m  ",
      " qWWWq          ",
      " qWWWqw m       ",
      " qqqqq          ",
      "            |   ",
      "     #:#:#      ",
      "     # j #      ",
      "     #   #      ",
      "     # # #  |   ",
      "     #####      ",
      "                ",
      "                ",
      "                ",
      "                "
    ],
    [
      "                ",
      " qqqqq          ",
      " q   q H     H  ",
      " q q q          ",
      " q   q  H       ",
      " qqqqq          ",
      "                ",
      "     #####      ",
      "     #####      ",
      "     #####      ",
      "     #####      ",
      "     #####      ",
      "                ",
      "                ",
      "                ",
      "                "
    ],
    [
      "                ",
      " :::::          ",
      " :   :          ",
      " : J :          ",
      " :   :          ",
      " :::::          ",
      "                ",
      "     55555      ",
      "                ",
      "      |         ",
      "                ",
      "     55555      ",
      "                ",
      "                ",
      "                ",
      "                "
    ],
    [
      "                ",
      "                ",
      "                ",
      "                ",
      "                ",
      "                ",
      "                ",
      "                ",
      "                ",
      "                ",
      "                ",
      "                ",
      "                ",
      "                ",
      "                ",
      "                "
    ]
  ]
}
