{
  "xsize": 16,
  "zsize": 16,
  "slices": [
    [
      "#$$#$$#$$#$$m$$#",
      "$33333333333333$",
      "$33333333333333$",
      "m33333333333333#",
      "$33333333333333$",
      "$eeeeeeeeeeeeee$",
      "#eeeeeeeeeeeeee#",
      "$eeeeeeeeeeeeee$",
      "$eeeeeeeeeeeeee$",
      "#eeeeeeleeeeeeem",
      "$eeeeeeeeeeeeee$",
      "$33333333333333$",
      "#33333333333333#",
      "$33333333333333$",
      "$33333333333333$",
      "#$$#$$m$$#$$#$$#"
    ],
    [
      "#######Um###m###",
      "#q:q wq:q  q:q #",
      "#qmqPwqmqP qmq&#",
      "mq0q wq0q  q0q #",
      "#   r     r    #",
      "#22  2222222222#",
      "#s   1    r  C #",
      "# 55O       &  #",
      "#             s#",
      "#     2l2      m",
      "#2222222222  22#",
      "#              #",
      "#rqmmmq  ss&sM #",
      "# q:0:q  sC s  #",
      "# qUmUq O&ss   #",
      "######mUm#######"
    ],
    [
      "#::#::#qq#::H::#",
      ":qmq wqmq  qmq :",
      ":q q  q q  q q :",
      "Hq:q'wq:q' q:q #",
      ":              :",
      ":?2  222222222?:",
      "#  %        %  #",
      "a              a",
      "a              a",
      "#    T%l2%     H",
      ":?222222222  2?:",
      ":  '           :",
      "# qmmmq  ss s  #",
      ": qI:Iq  s  s  :",
      ": q   q        :",
      "#::#::Hqq#::#::#"
    ],
    [
      "#::#::#::#::m::#",
      ":6H6 w6H6  6H6 :",
      ":              :",
      "m6H6 w6H6  6H6 #",
      ":              :",
      ":?222222222222?:",
      "# H           N#",
      "a              a",
      "a            H a",
      "#N  j 2l2  j   m",
      ":?222222222222?:",
      ":              :",
      "# qHHHq        #",
      ": qJ Jq        :",
      ": q666q        :",
      "#::#::m::#::#::#"
    ],
    [
      "############m###",
      "#mmm wmmm  mmm #",
      "#    w         #",
      "mmmm wmnm  mmm #",
      "m              #",
      "m22222222222222#",
      "#mmmmmmmmmmmmmm#",
      "m q  q    q  q #",
      "mmmmmmmmmmmmmmm#",
      "#   { 2l2  {   m",
      "#22222222222222m",
      "#              m",
      "# mmmmmn       #",
      "#              #",
      "# mmmmm        #",
      "######m#########"
    ],
    [
      "############m###",
      "################",
      "################",
      "m###############",
      "################",
      "################",
      "#mmmmmmmmmmmmmm#",
      "################",
      "#mmmmmmmmmmmmmm#",
      "#######l#######m",
      "################",
      "################",
      "################",
      "################",
      "################",
      "######m#########"
    ]
  ]
}
