{
  "xsize": 16,
  "zsize": 16,
  "slices": [
    [
      "################",
      "#eeeeeeeeeeeeee#",
      "#e3333eeeeeeeee#",
      "#e3333eeeeeeeee#",
      "#e3333eeeeeeeee#",
      "#e3333eeeeeeeee#",
      "#e3333eeeeeeeee#",
      "#eeeeeeeeeeeeee#",
      "#eeeeeeeeeeeeee#",
      "#eeeeeeleeeeeee#",
      "#eeeeeeeee3333e#",
      "#eeeeeeeee3333e#",
      "#eeeeeeeee3333e#",
      "#eeeeeeeee3333e#",
      "#eeeeeeeeeeeeee#",
      "################"
    ],
    [
      "################",
      "#              #",
      "#sss ss   s&ss #",
      "#sss ss   sC s #",
      "#       4    r #",
      "#s&ss sr  &sss #",
      "#s&ss s   s  M #",
      "#              #",
      "#  1     r &r  #",
      "# r Or3l3      #",
      "#     333      #",
      "#qmq w    q qq #",
      "#q:q w    qP q #",
      "#qJq w    qqqq #",
      "#              #",
      "################"
    ],
    [
      "################",
      "#              #",
      "#sss ss % ssss #",
      "#sss ss        #",
      "#   %      %   #",
      "#ss s s    sss #",
      "#ss%s s        #",
      "#              #",
      "#              #",
      "#    T3l3      #",
      "#     333%     #",
      "#qmq w    q qq #",
      "#q0q'     q %q #",
      "#qmq w%   qqqq #",
      "#              #",
      "################"
    ],
    [
      "################",
      "#              #",
      "#              #",
      "#              #",
      "#     N   \\    #",
      "#              #",
      "#              #",
      "# \\          \\ #",
      "#              #",
      "#     3l3   N  #",
      "#     333      #",
      "#mHm w    6666 #",
      "#      \\  6::6 #",
      "#6H6 w    6666 #",
      "#              #",
      "################"
    ],
    [
      "################",
      "#              #",
      "#      n       #",
      "#m m m m m m m #",
      "#              #",
      "#              #",
      "#          n   #",
      "#     qmmq     #",
      "#   j          #",
      "#     3l3      #",
      "#     333      #",
      "# m mwm m m m m#",
      "#    w         #",
      "# j  w         #",
      "#              #",
      "################"
    ],
    [
      "################",
      "################",
      "################",
      "#m#m#m#m#m#m#m##",
      "################",
      "################",
      "################",
      "################",
      "################",
      "#######l########",
      "################",
      "##m#m#m#m#m#m#m#",
      "################",
      "################",
      "################",
      "################"
    ]
  ]
}
