{
  "xsize": 16,
  "zsize": 16,
  "slices": [
    [
      "0000000000000000",
      "0  qqqq  oooo  0",
      "0  qEEq  oEEo  0",
      "0  qqqq  oooo  0",
      "0   u       u  0",
      "0  \"\"\"         0",
      "0     00 00    0",
      "0     0   0    0",
      "0     0 l 0    0",
      "0     00000    0",
      "0 }            0",
      "0 rrrr     qqqq0",
      "0 r  r  0  qWWq0",
      "0 r  r     qWWq0",
      "0 rrrr  }  qqqq0",
      "0000000000000000"
    ],
    [
      "0::::::::::::::0",
      ":  qqqq  oooo  :",
      ":  q((q  o((o  :",
      ":  qqqq  oooo  :",
      ":   {       {  :",
      ":              :",
      ":     00 00    :",
      ":     0   0    :",
      ":     0 l 0    :",
      ":     00000    :",
      ":              :",
      ": rrrr     QQQQ:",
      ": r((r  :  QWWQ:",
      ": r((r     QWWQ:",
      ": rrrr     QQQQ:",
      "0::::::::::::::0"
    ],
    [
      "0              0",
      "   |      |     ",
      "                ",
      "                ",
      "                ",
      "                ",
      "     UPPPPPI    ",
      "     U00000I    ",
      "     U00000I    ",
      "     UJJJJJI    ",
      "                ",
      "           QQQQ ",
      "        :  QQQQ ",
      "           QQQQ ",
      "   |       QQQQ ",
      "0              0"
    ],
    [
      "                ",
      "                ",
      "                ",
      "                ",
      "                ",
      "                ",
      "                ",
      "                ",
      "                ",
      "                ",
      "                ",
      "                ",
      "        |   |   ",
      "                ",
      "                ",
      "                "
    ],
    [
      "                ",
      "                ",
      "                ",
      "                ",
      "                ",
      "                ",
      "                ",
      "                ",
      "                ",
      "                ",
      "                ",
      "                ",
      "        |       ",
      "                ",
      "                ",
      "                "
    ],
    [
      "                ",
      "                ",
      "                ",
      "                ",
      "                ",
      "                ",
      "                ",
      "                ",
      "                ",
      "                ",
      "                ",
      "                ",
      "                ",
      "                ",
      "                ",
      "                "
    ]
  ]
}
