{
  "xsize": 16,
  "zsize": 16,
  "slices": [
    [
      "0000000000000000",
      "0    }         0",
      "0  ooooo       0",
      "0  oWWWo   qqq 0",
      "0  oWWWo   q&q 0",
      "0  ooooo   qqq 0",
      "0      0       0",
      "0    00 00     0",
      "0    0   0     0",
      "0    0 l 0  rrr0",
      "0    00000  r r0",
      "0           rrr0",
      "0 uu    }      0",
      "0  \"\"\"         0",
      "0             }0",
      "0000000000000000"
    ],
    [
      "0::::::::::::::0",
      ":              :",
      ":  oEEEo       :",
      ":  o   o   qQq :",
      ":  o   o   q?q :",
      ":  ooooo   qqq :",
      ":      :       :",
      ":    00 00     :",
      ":    0   0     :",
      ":    0 l 0  rrr:",
      ":    00000  r(r:",
      ":           rrr:",
      ": {  {         :",
      ":              :",
      ":              :",
      "0::::::::::::::0"
    ],
    [
      "0              0",
      "                ",
      "   ooooo        ",
      "   o(((o   qqq  ",
      "   o(((o   q(q  ",
      "   ooooo   qqq  ",
      "       :        ",
      "    UPPPPPI     ",
      "    U00000I     ",
      "    U00000I     ",
      "    UJJJJJI|    ",
      "                ",
      "                ",
      "                ",
      "                ",
      "0              0"
    ],
    [
      "                ",
      "                ",
      "                ",
      "   |       |    ",
      "                ",
      "                ",
      "       |        ",
      "                ",
      "                ",
      "                ",
      "                ",
      "                ",
      "                ",
      "                ",
      "                ",
      "                "
    ],
    [
      "                ",
      "                ",
      "                ",
      "                ",
      "                ",
      "                ",
      "       |        ",
      "                ",
      "                ",
      "                ",
      "                ",
      "                ",
      "                ",
      "                ",
      "                ",
      "                "
    ],
    [
      "                ",
      "                ",
      "                ",
      "                ",
      "                ",
      "                ",
      "                ",
      "                ",
      "                ",
      "                ",
      "                ",
      "                ",
      "                ",
      "                ",
      "                ",
      "                "
    ]
  ]
}
