{
  "xsize": 16,
  "zsize": 16,
  "slices": [
    [
      "#$$#$$#$$#$$m$$#",
      "$oooooooooooooo$",
      "$oooooooooooooo$",
      "moooooooooooooo#",
      "$oooooooooooooo$",
      "$oooooooooooooo$",
      "#eeeeeeeeeeeeee#",
      "$eeeeee77eeeeee$",
      "$eeeeee77eeeeee$",
      "#eeeeeeleeeeeeem",
      "$eeeeeeeeeeeeee$",
      "$oooooooooooooo$",
      "#oooooooooooooo#",
      "$oooooooooooooo$",
      "$oooooooooooooo$",
      "#$$#$$m$$#$$#$$#"
    ],
    [
      "####Um######m###",
      "NP52  2 VV F L #",
      "ms 2  2<55>   s#",
      "m2 2]52 ^^     #",
      "#   [7      ,  #",
      "#  s7,2O     C #",
      "#222 222222 222#",
      "# ^         ,  #",
      "# 5       r  & #",
      "#     2l2      m",
      "#   r 222      m",
      "#222 2222222 22N",
      "# VV   O 275]7 #",
      "# 55      77[7 #",
      "#s  ,&M  2s77, #",
      "######m######Nm#"
    ],
    [
      "#aa#qq#aa#aaHaa#",
      ": 62  2        a",
      "q %2  2        a",
      "H2 2  2        #",
      "a             %a",
      "a     2        a",
      "#222 22222? ?22#",
      "a              a",
      "a              a",
      "#    T2l2T   % H",
      "a     222      q",
      "a2?2 2?22222 22:",
      "#       %2     #",
      "a    %         a",
      "a        2     a",
      "#aa#aaHaa#aa#:q#"
    ],
    [
      "#aa#::#aa#aamaa#",
      "H  2  2        a",
      "H  2  2        a",
      "m22H  2     H  #",
      "a     2  \\     a",
      "a     2        a",
      "#222222222?2?22#",
      "a     n        a",
      "a              a",
      "#N    2l2      m",
      "a     222     Na",
      "a2?222?22222222a",
      "#  H     2  H  #",
      "a   \\    2     a",
      "a        2     a",
      "#aa#aamaa#aa#HH#"
    ],
    [
      "##########mmm###",
      "#  2  2        #",
      "#  m  2  n  m  #",
      "m22m  2     m  #",
      "#  mn 2     m  #",
      "#  m  2     m  #",
      "#22222222222222#",
      "#     {        #",
      "#mmmmmmmmmmmmmm#",
      "#     2l2      m",
      "#     222      #",
      "#22222222222222#",
      "#  m     2  m  #",
      "#  m     2  m  #",
      "#        2     #",
      "######m::#######"
    ],
    [
      "############m###",
      "#######mm#######",
      "################",
      "m###############",
      "################",
      "################",
      "################",
      "################",
      "#mmmmmmmmmmmmmm#",
      "#######l#######m",
      "################",
      "################",
      "################",
      "################",
      "################",
      "######m#########"
    ]
  ]
}
