{
  "xsize": 16,
  "zsize": 16,
  "slices": [
    [
      "################",
      "################",
      "##ffffffffffff##",
      "##ff}fffffffff##",
      "##ffffffff}fff##",
      "##ffffffffffff##",
      "#ffffffffffffff#",
      "#fff}ffffffffff#",
      "#ffffffffff}fff#",
      "#######l########",
      "#ffffffffffffff#",
      "##ff}fffffffff##",
      "##ffffffffffff##",
      "##fffff}ffff}f##",
      "################",
      "################"
    ],
    [
      "e8eeeeeeeeeeee8e",
      "8eeeee0cc0eeeee8",
      "eeqqqq   &C&  ee",
      "eeqWWq  \\  sssee",
      "eeqqqq      ssee",
      "eecc  }       ee",
      "e0cc0     ssss e",
      "e uu      &  C e",
      "eR      }     Re",
      "e  8   l   8   e",
      "ee&  ieeei  4 ee",
      "eess      \\  }ee",
      "eess  &     \\ ee",
      "ees&  qqqq  ssee",
      "8eeeeeWWWWeeeee8",
      "e8eeeeeeeeeeee8e"
    ],
    [
      "e8eeeeeeeeeeee8e",
      "8eeeee gg eeeee8",
      "eeqEEq    %   ee",
      "eeq  q     sssee",
      "eeqqqq      ssee",
      "ee{{          ee",
      "e gg           e",
      "e             %e",
      "e      %       e",
      "e      l       e",
      "ee    eee     ee",
      "eess      %   ee",
      "eess          ee",
      "ees         ssee",
      "8eeeee    eeeee8",
      "e8eeeeeeeeeeee8e"
    ],
    [
      "e8eeeeeeeeeeee8e",
      "8eeeee    eeeee8",
      "ee{  {   %    ee",
      "ee            ee",
      "ee{  {        ee",
      "ee  %       % ee",
      "e   %        % e",
      "e              e",
      "e  \\         \\ e",
      "e      l       e",
      "ee    eee     ee",
      "ee  %         ee",
      "ee            ee",
      "ee{         { ee",
      "8eeeee    eeeee8",
      "e8eeeeeeeeeeee8e"
    ],
    [
      "e8eeeeeeeeeeee8e",
      "8eeeeeqqqqeeeee8",
      "eeqqqq  n     ee",
      "eeq  q        ee",
      "eeqqqq   n    ee",
      "eeqq          ee",
      "eqqqqqqqqqqqqqqe",
      "e  n        n  e",
      "e   qqqqqqqq   e",
      "e      l       e",
      "ee n  eee   n ee",
      "ee  n      n  ee",
      "ee            ee",
      "ee  j      j  ee",
      "8eeeee    eeeee8",
      "e8eeeeeeeeeeee8e"
    ],
    [
      "################",
      "################",
      "################",
      "###0########0###",
      "################",
      "################",
      "###0########0###",
      "################",
      "################",
      "#######l########",
      "################",
      "################",
      "###0########0###",
      "################",
      "################",
      "################"
    ]
  ]
}
