{
  "xsize": 16,
  "zsize": 16,
  "slices": [
    [
      "bbbb_SSQQSS_bbbb",
      "bbbb_SSQQSS_bbbb",
      "bbbb_SSQQSS_bbbb",
      "bbbb_SSQQSS:bbbb",
      "____SSSQQGS_bbbb",
      "SvvSSSWQQSS_bbbb",
      "SvvSSSWQQS9_bbbb",
      "QQQQQQQQQSS_bbbb",
      "QQQQQQQQQSS_bbbb",
      "SSSSGSSSSvv_bbbb",
      "SSSSS9SSSvv_bbbb",
      "___:________bbbb",
      "bbbbbbbbbbbbbbbb",
      "bbbbbbbbbbbbbbbb",
      "bbbbbbbbbbbbbbbb",
      "bbbbbbbbbbbbbbbb"
    ],
    [
      "xGB_        _Bxx",
      "xxB_        _Bxx",
      "BBB_        _Bxx",
      "____        _Bxx",
      "         p  _Bxx",
      "            _BxG",
      "            _Bxx",
      "            _Bxx",
      "            _Bxx",
      "    K       _Bxx",
      "            _Bxx",
      "            _Bxx",
      "____________Bxxx",
      "BBBBBBBBBBBBxxxx",
      "xxxxxxxxxxxxxxxG",
      "xxGxxxxxxxxxxxGG"
    ],
    [
      "Fp%             ",
      "             w  ",
      "% w           F ",
      "               w",
      "                ",
      "             w K",
      "              A ",
      "              A ",
      "                ",
      "             w %",
      "                ",
      "             w% ",
      "             % F",
      " w   w   w w% G%",
      "      zz     G p",
      "  pw%   F % F%Kp"
    ],
    [
      "                ",
      "                ",
      "                ",
      "               9",
      "                ",
      "                ",
      "                ",
      "                ",
      "                ",
      "                ",
      "                ",
      "                ",
      "                ",
      "              p ",
      "             p  ",
      "   9            "
    ],
    [
      "                ",
      "                ",
      "                ",
      "                ",
      "                ",
      "                ",
      "                ",
      "                ",
      "                ",
      "                ",
      "                ",
      "                ",
      "                ",
      "                ",
      "                ",
      "                "
    ]
  ]
}
