{
  "xsize": 16,
  "zsize": 16,
  "slices": [
    [
      "bbbb_SSSSSS_bbbb",
      "bbbb_,Q,Q,Q_bbbb",
      "bbbb_,S,S,S_bbbb",
      "bbbb:QQQQQQ_bbbb",
      "____SSSSSSGS:___",
      "S,,QSvvv9SSSQ,,S",
      "SQSQSvvvSSSSQSQS",
      "S,,QSSSSSSS9Q,,S",
      "SQSQGSSSSSSSQSQS",
      "S,,QSSSWSvvSQ,,S",
      "SQSQvv9WSvvSQSQS",
      "___:vvSSSvvS____",
      "bbbb_QQQQQQ:bbbb",
      "bbbb_,S,S,S_bbbb",
      "bbbb_,Q,Q,Q_bbbb",
      "bbbb_SSSSSS_bbbb"
    ],
    [
      "xxB_        _BGG",
      "xxB_        _Bxx",
      "BBB_        _BBB",
      "____        ____",
      "          p     ",
      "                ",
      "                ",
      "                ",
      "    K           ",
      "                ",
      "                ",
      "                ",
      "____        ____",
      "BBB_        _BBB",
      "xxB_        _Bxx",
      "GGB_        _Bxx"
    ],
    [
      "F w          wKp",
      " %            % ",
      "w w          w w",
      "                ",
      "                ",
      "                ",
      "                ",
      "                ",
      "                ",
      "                ",
      "                ",
      "                ",
      "                ",
      "w w          w w",
      " %            % ",
      "pKw          w F"
    ],
    [
      "                ",
      "                ",
      "  9          9  ",
      "                ",
      "                ",
      "                ",
      "                ",
      "                ",
      "                ",
      "                ",
      "                ",
      "                ",
      "                ",
      "  9          9  ",
      "                ",
      "                "
    ],
    [
      "                ",
      "                ",
      "  g          g  ",
      "                ",
      "                ",
      "                ",
      "                ",
      "                ",
      "                ",
      "                ",
      "                ",
      "                ",
      "                ",
      "  g          g  ",
      "                ",
      "                "
    ]
  ],
  "palette": {
    "palette": [
      {
        "char": ",",
        "block": "minecraft:white_concrete"
      }
    ]
  }
}
