{
  "xsize": 16,
  "zsize": 16,
  "slices": [
    [
      "bbbb_SSSSSS_bbbb",
      "bbbb_QQQQQQ_bbbb",
      "bbbb_SSSSSS_bbbb",
      "bbbb:QQQQQQ_bbbb",
      "____SSSSSSGS:___",
      "SQSQSvvv9SSSQSQS",
      "SQSQSvvvSSSSQSQS",
      "SQSQSSSSSSS9QSQS",
      "SQSQGSSSSSSSQSQS",
      "SQSQSSSWSvvSQSQS",
      "SQSQvv9WSvvSQSQS",
      "___:vvSSSvvS____",
      "bbbb_QQQQQQ:bbbb",
      "bbbb_SSSSSS_bbbb",
      "bbbb_QQQQQQ_bbbb",
      "bbbb_SSSSSS_bbbb"
    ],
    [
      "xxB_        _BGG",
      "xxB_        _Bxx",
      "BBB_        _BBB",
      "____        ____",
      "          p     ",
      "                ",
      "                ",
      "                ",
      "    K           ",
      "                ",
      "                ",
      "                ",
      "____        ____",
      "BBB_        _BBB",
      "xxB_        _Bxx",
      "GGB_        _Bxx"
    ],
    [
      "F w          wKp",
      " %            % ",
      "w w          w w",
      "                ",
      "                ",
      "                ",
      "                ",
      "                ",
      "                ",
      "                ",
      "                ",
      "                ",
      "                ",
      "w w          w w",
      " %            % ",
      "pKw          w F"
    ],
    [
      "                ",
      "                ",
      "  9          9  ",
      "                ",
      "                ",
      "                ",
      "                ",
      "                ",
      "                ",
      "                ",
      "                ",
      "                ",
      "                ",
      "  9          9  ",
      "                ",
      "                "
    ],
    [
      "                ",
      "                ",
      "  g          g  ",
      "                ",
      "                ",
      "                ",
      "                ",
      "                ",
      "                ",
      "                ",
      "                ",
      "                ",
      "                ",
      "  g          g  ",
      "                ",
      "                "
    ]
  ]
}
