{
  "xsize": 16,
  "zsize": 16,
  "slices": [
    [
      "bbbbbbbbbbbbbbbb",
      "bbbbbbbbbbbbbbbb",
      "bbbbbbbbbbbbbbbb",
      "bbbbbbbbbbbbbbbb",
      "___:____________",
      "SSSSSSSSSSvvvSGS",
      "SS9SSSSSSSvvvSSS",
      "QQSSQQSSQQSSQQSS",
      "QQSSQQSSQQSSQQSS",
      "SSSSvvSSSSSSSSSS",
      "SGSSvvSS9SSSSSSS",
      "____________:___",
      "bbbbbbbbbbbbbbbb",
      "bbbbbbbbbbbbbbbb",
      "bbbbbbbbbbbbbbbb",
      "bbbbbbbbbbbbbbbb"
    ],
    [
      "GGxxxxxxxxxxxxxx",
      "Gxxxxxxxxxxxxxxx",
      "BBBBBBBBBBBBBBBB",
      "________________",
      "                ",
      "              K ",
      "                ",
      "                ",
      "                ",
      "                ",
      " p              ",
      "                ",
      "________________",
      "BBBBBBBBBBBBBBBB",
      "xxxxxxxxGxxxxxxx",
      "xxxxxxxGGxxxxxxx"
    ],
    [
      "p      %    K   ",
      "   F   cc      %",
      "w      w    w   ",
      "                ",
      "                ",
      "                ",
      "                ",
      "                ",
      "                ",
      "                ",
      "                ",
      "                ",
      "                ",
      "   w      w   w ",
      "%     zz    F  p",
      "  K       %    %"
    ],
    [
      "                ",
      "                ",
      "9      9    9   ",
      "                ",
      "                ",
      "                ",
      "                ",
      "                ",
      "                ",
      "                ",
      "                ",
      "                ",
      "                ",
      "   9      9   9 ",
      "                ",
      "                "
    ],
    [
      "                ",
      "                ",
      "                ",
      "                ",
      "                ",
      "                ",
      "                ",
      "                ",
      "                ",
      "                ",
      "                ",
      "                ",
      "                ",
      "                ",
      "                ",
      "                "
    ]
  ]
}
