{
  "xsize": 16,
  "zsize": 16,
  "slices": [
    [
      "bbbbbbbbbbbbbbbb",
      "bbbbbbbbbbbbbbbb",
      "bbbbbbbbbbbbbbbb",
      "bbbbbbbbbbbbbbbb",
      "bbbb________bbbb",
      "bbbb_SSSSSS_bbbb",
      "bbbb_SGGGGS_bbbb",
      "bbbb:vGGGGS_bbbb",
      "bbbb_9GGGGv:bbbb",
      "bbbb_SGGGGS_bbbb",
      "bbbb_SSSSSS_bbbb",
      "bbbb________bbbb",
      "bbbbbbbbbbbbbbbb",
      "bbbbbbbbbbbbbbbb",
      "bbbbbbbbbbbbbbbb",
      "bbbbbbbbbbbbbbbb"
    ],
    [
      "GxxxxxxxxxxxxxGx",
      "xxxxxxxxxxxxxxxx",
      "xxxxBBBBBBBBxxxx",
      "xxxB________Bxxx",
      "xxB_        _Bxx",
      "xxB_ w cc w _Bxx",
      "xxB_  ppKp  _Bxx",
      "xxB_  p     _Bxx",
      "xxB_     p  _Bxx",
      "xxB_  Kp p  _Bxx",
      "xxB_ w zz w _Bxx",
      "xxB_        _Bxx",
      "xxxB________Bxxx",
      "xxxxBBBBBBBBxxxx",
      "xxxxxxxxxxxxxxxx",
      "xGxxxxxxxxxxxxxG"
    ],
    [
      "p%            K ",
      "%G             %",
      "  w    w     w  ",
      "                ",
      "                ",
      "                ",
      "                ",
      "  w            F",
      "F            w  ",
      "                ",
      "                ",
      "                ",
      "                ",
      "  w     w    w  ",
      "%             G%",
      " K            %p"
    ],
    [
      "                ",
      " p              ",
      "                ",
      "                ",
      "                ",
      "                ",
      "                ",
      "  9             ",
      "             9  ",
      "                ",
      "                ",
      "                ",
      "                ",
      "                ",
      "              p ",
      "                "
    ],
    [
      "                ",
      "                ",
      "                ",
      "                ",
      "                ",
      "                ",
      "                ",
      "                ",
      "                ",
      "                ",
      "                ",
      "                ",
      "                ",
      "                ",
      "                ",
      "                "
    ]
  ]
}
