{
  "xsize": 16,
  "zsize": 16,
  "slices": [
    [
      "bbbbbbbbbbbbbbbb",
      "bbbbbbbbbbbbbbbb",
      "bbbbbbbbbbbbbbbb",
      "bbbbbbbbbbbbbbbb",
      "___:____________",
      "SSSSS9SSvvSSSSSS",
      "SGSSSSSSvvSSS9SS",
      "QQSSQQSSQQSSQQSS",
      "QQSSQQSSQQSSQQSS",
      "SvvSSSSSWWSSSSSS",
      "SvvSSS9SSSSSSSGS",
      "____________:___",
      "bbbbbbbbbbbbbbbb",
      "bbbbbbbbbbbbbbbb",
      "bbbbbbbbbbbbbbbb",
      "bbbbbbbbbbbbbbbb"
    ],
    [
      "GGxxxxxxxxxxxxxx",
      "Gxxxxxxxxxxxxxxx",
      "BBBBBBBBBBBBBBBB",
      "________________",
      "                ",
      "              K ",
      "                ",
      "                ",
      "                ",
      "                ",
      " p              ",
      "                ",
      "________________",
      "BBBBBBBBBBBBBBBB",
      "xxxxxxxxGxxxxxxx",
      "xxxxxxxGGxxxxxxx"
    ],
    [
      "%    K   p     %",
      "  cc      F    p",
      " w    w      w  ",
      "                ",
      "                ",
      "                ",
      "                ",
      "                ",
      "                ",
      "                ",
      "                ",
      "                ",
      "                ",
      "  w    w   w    ",
      "   zz   F     % ",
      "%   p       K  %"
    ],
    [
      "                ",
      "                ",
      " 9    9      9  ",
      "                ",
      "                ",
      "                ",
      "                ",
      "                ",
      "                ",
      "                ",
      "                ",
      "                ",
      "                ",
      "  9    9   9    ",
      "                ",
      "                "
    ],
    [
      "                ",
      "                ",
      "                ",
      "                ",
      "                ",
      "                ",
      "                ",
      "                ",
      "                ",
      "                ",
      "                ",
      "                ",
      "                ",
      "                ",
      "                ",
      "                "
    ]
  ]
}
