{
  "xsize": 16,
  "zsize": 16,
  "slices": [
    [
      "bbbbbbbbbbbbbbbb",
      "bbbbbbbbbbbbbbbb",
      "bbbbbbbbbbbbbbbb",
      "bbbbbbbbbbbbbbbb",
      "___:________bbbb",
      "SQSQSSSQvvSGbbbb",
      "SQSQSSSQvvS_bbbb",
      "SQSQSSSQSSSGbbbb",
      "SQSQSSSQWSSGbbbb",
      "SQSQS9SQWSS_bbbb",
      "SQSQSSSQSSSGbbbb",
      "___:________bbbb",
      "bbbbbbbbbbbbbbbb",
      "bbbbbbbbbbbbbbbb",
      "bbbbbbbbbbbbbbbb",
      "bbbbbbbbbbbbbbbb"
    ],
    [
      "xxxxxxxxGxxxxxxx",
      "xxxxxxxxxxxxxxxx",
      "BBBBBBBBBBBBxxxx",
      "____________Bxxx",
      "          w _BGx",
      "          wp_BxG",
      "          wv_Bxx",
      "         v p_Bxx",
      "          vK_Bxx",
      "          w _Bxx",
      "          wp_BxG",
      "          w _BGx",
      "____________Bxxx",
      "BBBBBBBBBBBBxxxx",
      "xxxxxxxxxxxxxxxx",
      "xxxxxxxGxxxxxxxx"
    ],
    [
      "F       K      %",
      " cc             ",
      "  w  w   w      ",
      "                ",
      "          %  %p ",
      "          %    K",
      "             G  ",
      "              F%",
      "               %",
      "           % G  ",
      "          %    K",
      "             %p ",
      "                ",
      "  w  w   w      ",
      " zz             ",
      "%      p       F"
    ],
    [
      "                ",
      "                ",
      "         9      ",
      "                ",
      "                ",
      "                ",
      "             p  ",
      "                ",
      "                ",
      "             p  ",
      "                ",
      "                ",
      "                ",
      "         9      ",
      "                ",
      "                "
    ],
    [
      "                ",
      "                ",
      "                ",
      "                ",
      "                ",
      "                ",
      "                ",
      "                ",
      "                ",
      "                ",
      "                ",
      "                ",
      "                ",
      "                ",
      "                ",
      "                "
    ]
  ]
}
