{
  "xsize": 16,
  "zsize": 16,
  "slices": [
    [
      "bbbb_SSSSSS_bbbb",
      "bbbb_,Q,Q,Q_bbbb",
      "bbbb_,S,S,S_bbbb",
      "bbbb:QQQQQQ_bbbb",
      "____SSSSSSSS:___",
      "S,,QSvvSSSSGQ,,S",
      "SQSQSvv9SSSSQSQS",
      "S,,QSvvSSSSSQ,,S",
      "SQSQSSSSSvvvQSQS",
      "S,,QSSSSWvvvQ,,S",
      "SQSQSGSSSS9SQSQS",
      "___:____________",
      "bbbbbbbbbbbbbbbb",
      "bbbbbbbbbbbbbbbb",
      "bbbbbbbbbbbbbbbb",
      "bbbbbbbbbbbbbbbb"
    ],
    [
      "GxB_        _Bxx",
      "xxB_        _BxG",
      "BBB_        _BBB",
      "____        ____",
      "                ",
      "           K    ",
      "                ",
      "                ",
      "                ",
      "                ",
      "     p          ",
      "                ",
      "________________",
      "BBBBBBBBBBBBBBBB",
      "Gxxxxxxxxxxxxxxx",
      "GxxxxxxxxxxxxxxG"
    ],
    [
      "p%            % ",
      "               K",
      "w w          w w",
      "                ",
      "                ",
      "                ",
      "                ",
      "                ",
      "                ",
      "                ",
      "                ",
      "                ",
      "                ",
      " ww   w   w  ww ",
      "K   G  zz  G    ",
      "p  F %%  F  %  p"
    ],
    [
      "                ",
      "                ",
      "  9          9  ",
      "                ",
      "                ",
      "                ",
      "                ",
      "                ",
      "                ",
      "                ",
      "                ",
      "                ",
      "                ",
      " 9           9  ",
      "    p      p    ",
      "                "
    ],
    [
      "                ",
      "                ",
      "  g          g  ",
      "                ",
      "                ",
      "                ",
      "                ",
      "                ",
      "                ",
      "                ",
      "                ",
      "                ",
      "                ",
      "                ",
      "                ",
      "                "
    ]
  ],
  "palette": {
    "palette": [
      {
        "char": ",",
        "block": "minecraft:white_concrete"
      }
    ]
  }
}
