{
  "xsize": 16,
  "zsize": 16,
  "slices": [
    [
      "bbbbbbbbbbbbbbbb",
      "bbbbbbbbbbbbbbbb",
      "bbbbbbbbbbbbbbbb",
      "bbbbbbbbbbbbbbbb",
      "___:____________",
      "SSvvSS9SSSSSSSGS",
      "SSvvSSSSSWWSSSSS",
      "QQSSQQSSQQSSQQSS",
      "QQSSQQSSQQSSQQSS",
      "SSSSSSSSSSSSvvvS",
      "SGSSSSSSSSS9vvvS",
      "____________:___",
      "bbbbbbbbbbbbbbbb",
      "bbbbbbbbbbbbbbbb",
      "bbbbbbbbbbbbbbbb",
      "bbbbbbbbbbbbbbbb"
    ],
    [
      "GGxxxxxxxxxxxxxx",
      "Gxxxxxxxxxxxxxxx",
      "BBBBBBBBBBBBBBBB",
      "________________",
      "                ",
      "              K ",
      "                ",
      "                ",
      "                ",
      "                ",
      " p              ",
      "                ",
      "________________",
      "BBBBBBBBBBBBBBBB",
      "xxxxxxxxGxxxxxxx",
      "xxxxxxxGGxxxxxxx"
    ],
    [
      "pK        %    %",
      "p   cc  F     w%",
      "  w    w    w   ",
      "                ",
      "                ",
      "                ",
      "                ",
      "                ",
      "                ",
      "                ",
      "                ",
      "                ",
      "                ",
      "    w w  w    w ",
      "% F     p  zz   ",
      "%      pK    %  "
    ],
    [
      "                ",
      "              9 ",
      "                ",
      "                ",
      "                ",
      "                ",
      "                ",
      "                ",
      "                ",
      "                ",
      "                ",
      "                ",
      "                ",
      "      9         ",
      "                ",
      "                "
    ],
    [
      "                ",
      "                ",
      "                ",
      "                ",
      "                ",
      "                ",
      "                ",
      "                ",
      "                ",
      "                ",
      "                ",
      "                ",
      "                ",
      "                ",
      "                ",
      "                "
    ]
  ]
}
